Workbook

Sheet CONFIGURATION
A1: CONFIGURATION DU FICHIER - ANNÉE 2026
A3: ANNÉE
A4: Année en cours | B4: 2026
A6: DROITS ANNUELS
A7: Type | B7: Droit annuel | C7: Report N-1
A8: CN | B8: 24 | C8: 0
A9: JC | B9: 13 | C9: 0
A11: PÉRIODES (4 SEMAINES)
A12: Période | B12: Début | C12: Fin | D12: Max heures
A13: Période | B13: Début | C13: Fin | D13: Max heures
A14: P1 | B14: 46034 | C14: 46061 | D14: 160
A15: P2 | B15: 46062 | C15: 46089 | D15: 160
A16: P3 | B16: 46090 | C16: 46117 | D16: 160
A17: P4 | B17: 46118 | C17: 46145 | D17: 160
A18: P5 | B18: 46146 | C18: 46173 | D18: 160
A19: P6 | B19: 46174 | C19: 46201 | D19: 160
A20: P7 | B20: 46202 | C20: 46229 | D20: 160
A21: P8 | B21: 46230 | C21: 46257 | D21: 160
A22: P9 | B22: 46258 | C22: 46285 | D22: 160
A23: P10 | B23: 46286 | C23: 46313 | D23: 160
A24: P11 | B24: 46314 | C24: 46341 | D24: 160
A25: P12 | B25: 46342 | C25: 46369 | D25: 160
A26: P13 | B26: 46370 | C26: 46397 | D26: 160
A27: HORAIRES PRESTATIONS
A28: Code | B28: Nom | C28: Début | D28: Fin | E28: H.tot | F28: H.nuit | G28: Couleur
A29: 101 | B29: Matin PACO | C29: 06:00 | D29: 14:00 | E29: 8 | F29: 2
A30: 102 | B30: Matin RCCA | C30: 06:00 | D30: 14:00 | E30: 8 | F30: 2
A31: 111 | B31: PM PACO | C31: 14:00 | D31: 22:00 | E31: 8 | F31: 2
A32: 112 | B32: PM RCCA | C32: 14:00 | D32: 22:00 | E32: 8 | F32: 2
A33: 121 | B33: Nuit PACO | C33: 22:00 | D33: 06:00 | E33: 8 | F33: 8
A34: 6101 | B34: Sam Matin PACO | C34: 06:00 | D34: 14:00 | E34: 8 | F34: 2
A35: 6102 | B35: Sam Matin RCCA | C35: 06:00 | D35: 14:00 | E35: 8 | F35: 2
A36: 6111 | B36: Sam PM PACO | C36: 14:00 | D36: 22:00 | E36: 8 | F36: 2
A37: 6112 | B37: Sam PM RCCA | C37: 14:00 | D37: 22:00 | E37: 8 | F37: 2
A38: 6121 | B38: Sam Nuit PACO | C38: 22:00 | D38: 06:00 | E38: 8 | F38: 8
A39: 7101 | B39: Dim Matin PACO | C39: 06:00 | D39: 14:00 | E39: 8 | F39: 2
A40: 7102 | B40: Dim Matin RCCA | C40: 06:00 | D40: 14:00 | E40: 8 | F40: 2
... A46: X_10 | B46: Extra 10-18 | C46: 10:00 | D46: 18:00 | E46: 8 | F46: 0
A48: CODES ABSENCES
A49: Code | B49: Description | G49: Couleur
...

Sheet TABLEAU DE BORD
A1: TABLEAU DE BORD - ANNÉE 2026
A3: SOLDES CONGÉS
A5: Type | B5: Droit | C5: Report N-1 | D5: Total | E5: Pris | F5: Restant
A6: CN | B6: =CONFIGURATION!B8 | C6: =CONFIGURATION!C8 | D6: =B6+C6 | E6: =B31 | F6: =B6+C6-E6
A7: JC | B7: =CONFIGURATION!B9 | C7: =CONFIGURATION!C9 | D7: =B7+C7 | E7: =B32 | F7: =B7+C7-E7
A9: STATISTIQUES ANNUELLES
A11: Code | B11: Jours | C11: H.tot | D11: H.nuit
A12: 101 | B12: =COUNTIF(Janvier!B6:P6,"101")+COUNTIF(Janvier!B12:R12,"101")+COUNTIF(Février!B6:P6,"101")+COUNTIF(Février!B12:R12,"101")+COUNTIF(Mars!B6:P6,"101")+COUNTIF(Mars!B12:R12,"101")+COUNTIF(Avril!B6:P6,"101")+COUNTIF(Avril!B12:R12,"101")+COUNTIF(Mai!B6:P6,"101")+COUNTIF(Mai!B12:R12,"101")+COUNTIF(Juin!B6:P6,"101")+COUNTIF(Juin!B12:R12,"101")+COUNTIF(Juillet!B6:P6,"101")+COUNTIF(Juillet!B12:R12,"101")+COUNTIF(Août!B6:P6,"101")+COUNTIF(Août!B12:R12,"101")+COUNTIF(Septembre!B6:P6,"101")+COUNTIF(Septembre!B12:R12,"101")+COUNTIF(Octobre!B6:P6,"101")+COUNTIF(Octobre!B12:R12,"101")+COUNTIF(Novembre!B6:P6,"101")+COUNTIF(Novembre!B12:R12,"101")+COUNTIF(Décembre!B6:P6,"101")+COUNTIF(Décembre!B12:R12,"101") | C12: =B12*8 | D12: =B12*2
A13: 102 | B13: =COUNTIF(Janvier!B6:P6,"102")+COUNTIF(Janvier!B12:R12,"102")+COUNTIF(Février!B6:P6,"102")+COUNTIF(Février!B12:R12,"102")+COUNTIF(Mars!B6:P6,"102")+COUNTIF(Mars!B12:R12,"102")+COUNTIF(Avril!B6:P6,"102")+COUNTIF(Avril!B12:R12,"102")+COUNTIF(Mai!B6:P6,"102")+COUNTIF(Mai!B12:R12,"102")+COUNTIF(Juin!B6:P6,"102")+COUNTIF(Juin!B12:R12,"102")+COUNTIF(Juillet!B6:P6,"102")+COUNTIF(Juillet!B12:R12,"102")+COUNTIF(Août!B6:P6,"102")+COUNTIF(Août!B12:R12,"102")+COUNTIF(Septembre!B6:P6,"102")+COUNTIF(Septembre!B12:R12,"102")+COUNTIF(Octobre!B6:P6,"102")+COUNTIF(Octobre!B12:R12,"102")+COUNTIF(Novembre!B6:P6,"102")+COUNTIF(Novembre!B12:R12,"102")+COUNTIF(Décembre!B6:P6,"102")+COUNTIF(Décembre!B12:R12,"102") | C13: =B13*8 | D13: =B13*2
A14: 111 | B14: =COUNTIF(Janvier!B6:P6,"111")+COUNTIF(Janvier!B12:R12,"111")+COUNTIF(Février!B6:P6,"111")+COUNTIF(Février!B12:R12,"111")+COUNTIF(Mars!B6:P6,"111")+COUNTIF(Mars!B12:R12,"111")+COUNTIF(Avril!B6:P6,"111")+COUNTIF(Avril!B12:R12,"111")+COUNTIF(Mai!B6:P6,"111")+COUNTIF(Mai!B12:R12,"111")+COUNTIF(Juin!B6:P6,"111")+COUNTIF(Juin!B12:R12,"111")+COUNTIF(Juillet!B6:P6,"111")+COUNTIF(Juillet!B12:R12,"111")+COUNTIF(Août!B6:P6,"111")+COUNTIF(Août!B12:R12,"111")+COUNTIF(Septembre!B6:P6,"111")+COUNTIF(Septembre!B12:R12,"111")+COUNTIF(Octobre!B6:P6,"111")+COUNTIF(Octobre!B12:R12,"111")+COUNTIF(Novembre!B6:P6,"111")+COUNTIF(Novembre!B12:R12,"111")+COUNTIF(Décembre!B6:P6,"111")+COUNTIF(Décembre!B12:R12,"111") | C14: =B14*8 | D14: =B14*2
A15: 112 | B15: =COUNTIF(Janvier!B6:P6,"112")+COUNTIF(Janvier!B12:R12,"112")+COUNTIF(Février!B6:P6,"112")+COUNTIF(Février!B12:R12,"112")+COUNTIF(Mars!B6:P6,"112")+COUNTIF(Mars!B12:R12,"112")+COUNTIF(Avril!B6:P6,"112")+COUNTIF(Avril!B12:R12,"112")+COUNTIF(Mai!B6:P6,"112")+COUNTIF(Mai!B12:R12,"112")+COUNTIF(Juin!B6:P6,"112")+COUNTIF(Juin!B12:R12,"112")+COUNTIF(Juillet!B6:P6,"112")+COUNTIF(Juillet!B12:R12,"112")+COUNTIF(Août!B6:P6,"112")+COUNTIF(Août!B12:R12,"112")+COUNTIF(Septembre!B6:P6,"112")+COUNTIF(Septembre!B12:R12,"112")+COUNTIF(Octobre!B6:P6,"112")+COUNTIF(Octobre!B12:R12,"112")+COUNTIF(Novembre!B6:P6,"112")+COUNTIF(Novembre!B12:R12,"112")+COUNTIF(Décembre!B6:P6,"112")+COUNTIF(Décembre!B12:R12,"112") | C15: =B15*8 | D15: =B15*2
A16: 121 | B16: =COUNTIF(Janvier!B6:P6,"121")+COUNTIF(Janvier!B12:R12,"121")+COUNTIF(Février!B6:P6,"121")+COUNTIF(Février!B12:R12,"121")+COUNTIF(Mars!B6:P6,"121")+COUNTIF(Mars!B12:R12,"121")+COUNTIF(Avril!B6:P6,"121")+COUNTIF(Avril!B12:R12,"121")+COUNTIF(Mai!B6:P6,"121")+COUNTIF(Mai!B12:R12,"121")+COUNTIF(Juin!B6:P6,"121")+COUNTIF(Juin!B12:R12,"121")+COUNTIF(Juillet!B6:P6,"121")+COUNTIF(Juillet!B12:R12,"121")+COUNTIF(Août!B6:P6,"121")+COUNTIF(Août!B12:R12,"121")+COUNTIF(Septembre!B6:P6,"121")+COUNTIF(Septembre!B12:R12,"121")+COUNTIF(Octobre!B6:P6,"121")+COUNTIF(Octobre!B12:R12,"121")+COUNTIF(Novembre!B6:P6,"121")+COUNTIF(Novembre!B12:R12,"121")+COUNTIF(Décembre!B6:P6,"121")+COUNTIF(Décembre!B12:R12,"121") | C16: =B16*8 | D16: =B16*8
A17: 6101 | B17: =COUNTIF(Janvier!B6:P6,"6101")+COUNTIF(Janvier!B12:R12,"6101")+COUNTIF(Février!B6:P6,"6101")+COUNTIF(Février!B12:R12,"6101")+COUNTIF(Mars!B6:P6,"6101")+COUNTIF(Mars!B12:R12,"6101")+COUNTIF(Avril!B6:P6,"6101")+COUNTIF(Avril!B12:R12,"6101")+COUNTIF(Mai!B6:P6,"6101")+COUNTIF(Mai!B12:R12,"6101")+COUNTIF(Juin!B6:P6,"6101")+COUNTIF(Juin!B12:R12,"6101")+COUNTIF(Juillet!B6:P6,"6101")+COUNTIF(Juillet!B12:R12,"6101")+COUNTIF(Août!B6:P6,"6101")+COUNTIF(Août!B12:R12,"6101")+COUNTIF(Septembre!B6:P6,"6101")+COUNTIF(Septembre!B12:R12,"6101")+COUNTIF(Octobre!B6:P6,"6101")+COUNTIF(Octobre!B12:R12,"6101")+COUNTIF(Novembre!B6:P6,"6101")+COUNTIF(Novembre!B12:R12,"6101")+COUNTIF(Décembre!B6:P6,"6101")+COUNTIF(Décembre!B12:R12,"6101") | C17: =B17*8 | D17: =B17*2
A18: 6102 | B18: =COUNTIF(Janvier!B6:P6,"6102")+COUNTIF(Janvier!B12:R12,"6102")+COUNTIF(Février!B6:P6,"6102")+COUNTIF(Février!B12:R12,"6102")+COUNTIF(Mars!B6:P6,"6102")+COUNTIF(Mars!B12:R12,"6102")+COUNTIF(Avril!B6:P6,"6102")+COUNTIF(Avril!B12:R12,"6102")+COUNTIF(Mai!B6:P6,"6102")+COUNTIF(Mai!B12:R12,"6102")+COUNTIF(Juin!B6:P6,"6102")+COUNTIF(Juin!B12:R12,"6102")+COUNTIF(Juillet!B6:P6,"6102")+COUNTIF(Juillet!B12:R12,"6102")+COUNTIF(Août!B6:P6,"6102")+COUNTIF(Août!B12:R12,"6102")+COUNTIF(Septembre!B6:P6,"6102")+COUNTIF(Septembre!B12:R12,"6102")+COUNTIF(Octobre!B6:P6,"6102")+COUNTIF(Octobre!B12:R12,"6102")+COUNTIF(Novembre!B6:P6,"6102")+COUNTIF(Novembre!B12:R12,"6102")+COUNTIF(Décembre!B6:P6,"6102")+COUNTIF(Décembre!B12:R12,"6102") | C18: =B18*8 | D18: =B18*2
A19: 6111 | B19: =COUNTIF(Janvier!B6:P6,"6111")+COUNTIF(Janvier!B12:R12,"6111")+COUNTIF(Février!B6:P6,"6111")+COUNTIF(Février!B12:R12,"6111")+COUNTIF(Mars!B6:P6,"6111")+COUNTIF(Mars!B12:R12,"6111")+COUNTIF(Avril!B6:P6,"6111")+COUNTIF(Avril!B12:R12,"6111")+COUNTIF(Mai!B6:P6,"6111")+COUNTIF(Mai!B12:R12,"6111")+COUNTIF(Juin!B6:P6,"6111")+COUNTIF(Juin!B12:R12,"6111")+COUNTIF(Juillet!B6:P6,"6111")+COUNTIF(Juillet!B12:R12,"6111")+COUNTIF(Août!B6:P6,"6111")+COUNTIF(Août!B12:R12,"6111")+COUNTIF(Septembre!B6:P6,"6111")+COUNTIF(Septembre!B12:R12,"6111")+COUNTIF(Octobre!B6:P6,"6111")+COUNTIF(Octobre!B12:R12,"6111")+COUNTIF(Novembre!B6:P6,"6111")+COUNTIF(Novembre!B12:R12,"6111")+COUNTIF(Décembre!B6:P6,"6111")+COUNTIF(Décembre!B12:R12,"6111") | C19: =B19*8 | D19: =B19*2
A20: 6112 | B20: =COUNTIF(Janvier!B6:P6,"6112")+COUNTIF(Janvier!B12:R12,"6112")+COUNTIF(Février!B6:P6,"6112")+COUNTIF(Février!B12:R12,"6112")+COUNTIF(Mars!B6:P6,"6112")+COUNTIF(Mars!B12:R12,"6112")+COUNTIF(Avril!B6:P6,"6112")+COUNTIF(Avril!B12:R12,"6112")+COUNTIF(Mai!B6:P6,"6112")+COUNTIF(Mai!B12:R12,"6112")+COUNTIF(Juin!B6:P6,"6112")+COUNTIF(Juin!B12:R12,"6112")+COUNTIF(Juillet!B6:P6,"6112")+COUNTIF(Juillet!B12:R12,"6112")+COUNTIF(Août!B6:P6,"6112")+COUNTIF(Août!B12:R12,"6112")+COUNTIF(Septembre!B6:P6,"6112")+COUNTIF(Septembre!B12:R12,"6112")+COUNTIF(Octobre!B6:P6,"6112")+COUNTIF(Octobre!B12:R12,"6112")+COUNTIF(Novembre!B6:P6,"6112")+COUNTIF(Novembre!B12:R12,"6112")+COUNTIF(Décembre!B6:P6,"6112")+COUNTIF(Décembre!B12:R12,"6112") | C20: =B20*8 | D20: =B20*2
A21: 6121 | B21: =COUNTIF(Janvier!B6:P6,"6121")+COUNTIF(Janvier!B12:R12,"6121")+COUNTIF(Février!B6:P6,"6121")+COUNTIF(Février!B12:R12,"6121")+COUNTIF(Mars!B6:P6,"6121")+COUNTIF(Mars!B12:R12,"6121")+COUNTIF(Avril!B6:P6,"6121")+COUNTIF(Avril!B12:R12,"6121")+COUNTIF(Mai!B6:P6,"6121")+COUNTIF(Mai!B12:R12,"6121")+COUNTIF(Juin!B6:P6,"6121")+COUNTIF(Juin!B12:R12,"6121")+COUNTIF(Juillet!B6:P6,"6121")+COUNTIF(Juillet!B12:R12,"6121")+COUNTIF(Août!B6:P6,"6121")+COUNTIF(Août!B12:R12,"6121")+COUNTIF(Septembre!B6:P6,"6121")+COUNTIF(Septembre!B12:R12,"6121")+COUNTIF(Octobre!B6:P6,"6121")+COUNTIF(Octobre!B12:R12,"6121")+COUNTIF(Novembre!B6:P6,"6121")+COUNTIF(Novembre!B12:R12,"6121")+COUNTIF(Décembre!B6:P6,"6121")+COUNTIF(Décembre!B12:R12,"6121") | C21: =B21*8 | D21: =B21*8
A22: 7101 | B22: =COUNTIF(Janvier!B6:P6,"7101")+COUNTIF(Janvier!B12:R12,"7101")+COUNTIF(Février!B6:P6,"7101")+COUNTIF(Février!B12:R12,"7101")+COUNTIF(Mars!B6:P6,"7101")+COUNTIF(Mars!B12:R12,"7101")+COUNTIF(Avril!B6:P6,"7101")+COUNTIF(Avril!B12:R12,"7101")+COUNTIF(Mai!B6:P6,"7101")+COUNTIF(Mai!B12:R12,"7101")+COUNTIF(Juin!B6:P6,"7101")+COUNTIF(Juin!B12:R12,"7101")+COUNTIF(Juillet!B6:P6,"7101")+COUNTIF(Juillet!B12:R12,"7101")+COUNTIF(Août!B6:P6,"7101")+COUNTIF(Août!B12:R12,"7101")+COUNTIF(Septembre!B6:P6,"7101")+COUNTIF(Septembre!B12:R12,"7101")+COUNTIF(Octobre!B6:P6,"7101")+COUNTIF(Octobre!B12:R12,"7101")+COUNTIF(Novembre!B6:P6,"7101")+COUNTIF(Novembre!B12:R12,"7101")+COUNTIF(Décembre!B6:P6,"7101")+COUNTIF(Décembre!B12:R12,"7101") | C22: =B22*8 | D22: =B22*2
A23: 7102 | B23: =COUNTIF(Janvier!B6:P6,"7102")+COUNTIF(Janvier!B12:R12,"7102")+COUNTIF(Février!B6:P6,"7102")+COUNTIF(Février!B12:R12,"7102")+COUNTIF(Mars!B6:P6,"7102")+COUNTIF(Mars!B12:R12,"7102")+COUNTIF(Avril!B6:P6,"7102")+COUNTIF(Avril!B12:R12,"7102")+COUNTIF(Mai!B6:P6,"7102")+COUNTIF(Mai!B12:R12,"7102")+COUNTIF(Juin!B6:P6,"7102")+COUNTIF(Juin!B12:R12,"7102")+COUNTIF(Juillet!B6:P6,"7102")+COUNTIF(Juillet!B12:R12,"7102")+COUNTIF(Août!B6:P6,"7102")+COUNTIF(Août!B12:R12,"7102")+COUNTIF(Septembre!B6:P6,"7102")+COUNTIF(Septembre!B12:R12,"7102")+COUNTIF(Octobre!B6:P6,"7102")+COUNTIF(Octobre!B12:R12,"7102")+COUNTIF(Novembre!B6:P6,"7102")+COUNTIF(Novembre!B12:R12,"7102")+COUNTIF(Décembre!B6:P6,"7102")+COUNTIF(Décembre!B12:R12,"7102") | C23: =B23*8 | D23: =B23*2
A24: 7111 | B24: =COUNTIF(Janvier!B6:P6,"7111")+COUNTIF(Janvier!B12:R12,"7111")+COUNTIF(Février!B6:P6,"7111")+COUNTIF(Février!B12:R12,"7111")+COUNTIF(Mars!B6:P6,"7111")+COUNTIF(Mars!B12:R12,"7111")+COUNTIF(Avril!B6:P6,"7111")+COUNTIF(Avril!B12:R12,"7111")+COUNTIF(Mai!B6:P6,"7111")+COUNTIF(Mai!B12:R12,"7111")+COUNTIF(Juin!B6:P6,"7111")+COUNTIF(Juin!B12:R12,"7111")+COUNTIF(Juillet!B6:P6,"7111")+COUNTIF(Juillet!B12:R12,"7111")+COUNTIF(Août!B6:P6,"7111")+COUNTIF(Août!B12:R12,"7111")+COUNTIF(Septembre!B6:P6,"7111")+COUNTIF(Septembre!B12:R12,"7111")+COUNTIF(Octobre!B6:P6,"7111")+COUNTIF(Octobre!B12:R12,"7111")+COUNTIF(Novembre!B6:P6,"7111")+COUNTIF(Novembre!B12:R12,"7111")+COUNTIF(Décembre!B6:P6,"7111")+COUNTIF(Décembre!B12:R12,"7111") | C24: =B24*8 | D24: =B24*2
A25: 7112 | B25: =COUNTIF(Janvier!B6:P6,"7112")+COUNTIF(Janvier!B12:R12,"7112")+COUNTIF(Février!B6:P6,"7112")+COUNTIF(Février!B12:R12,"7112")+COUNTIF(Mars!B6:P6,"7112")+COUNTIF(Mars!B12:R12,"7112")+COUNTIF(Avril!B6:P6,"7112")+COUNTIF(Avril!B12:R12,"7112")+COUNTIF(Mai!B6:P6,"7112")+COUNTIF(Mai!B12:R12,"7112")+COUNTIF(Juin!B6:P6,"7112")+COUNTIF(Juin!B12:R12,"7112")+COUNTIF(Juillet!B6:P6,"7112")+COUNTIF(Juillet!B12:R12,"7112")+COUNTIF(Août!B6:P6,"7112")+COUNTIF(Août!B12:R12,"7112")+COUNTIF(Septembre!B6:P6,"7112")+COUNTIF(Septembre!B12:R12,"7112")+COUNTIF(Octobre!B6:P6,"7112")+COUNTIF(Octobre!B12:R12,"7112")+COUNTIF(Novembre!B6:P6,"7112")+COUNTIF(Novembre!B12:R12,"7112")+COUNTIF(Décembre!B6:P6,"7112")+COUNTIF(Décembre!B12:R12,"7112") | C25: =B25*8 | D25: =B25*2
A26: 7121 | B26: =COUNTIF(Janvier!B6:P6,"7121")+COUNTIF(Janvier!B12:R12,"7121")+COUNTIF(Février!B6:P6,"7121")+COUNTIF(Février!B12:R12,"7121")+COUNTIF(Mars!B6:P6,"7121")+COUNTIF(Mars!B12:R12,"7121")+COUNTIF(Avril!B6:P6,"7121")+COUNTIF(Avril!B12:R12,"7121")+COUNTIF(Mai!B6:P6,"7121")+COUNTIF(Mai!B12:R12,"7121")+COUNTIF(Juin!B6:P6,"7121")+COUNTIF(Juin!B12:R12,"7121")+COUNTIF(Juillet!B6:P6,"7121")+COUNTIF(Juillet!B12:R12,"7121")+COUNTIF(Août!B6:P6,"7121")+COUNTIF(Août!B12:R12,"7121")+COUNTIF(Septembre!B6:P6,"7121")+COUNTIF(Septembre!B12:R12,"7121")+COUNTIF(Octobre!B6:P6,"7121")+COUNTIF(Octobre!B12:R12,"7121")+COUNTIF(Novembre!B6:P6,"7121")+COUNTIF(Novembre!B12:R12,"7121")+COUNTIF(Décembre!B6:P6,"7121")+COUNTIF(Décembre!B12:R12,"7121") | C26: =B26*8 | D26: =B26*8
A27: X_AM | B27: =COUNTIF(Janvier!B6:P6,"X_AM")+COUNTIF(Janvier!B12:R12,"X_AM")+COUNTIF(Février!B6:P6,"X_AM")+COUNTIF(Février!B12:R12,"X_AM")+COUNTIF(Mars!B6:P6,"X_AM")+COUNTIF(Mars!B12:R12,"X_AM")+COUNTIF(Avril!B6:P6,"X_AM")+COUNTIF(Avril!B12:R12,"X_AM")+COUNTIF(Mai!B6:P6,"X_AM")+COUNTIF(Mai!B12:R12,"X_AM")+COUNTIF(Juin!B6:P6,"X_AM")+COUNTIF(Juin!B12:R12,"X_AM")+COUNTIF(Juillet!B6:P6,"X_AM")+COUNTIF(Juillet!B12:R12,"X_AM")+COUNTIF(Août!B6:P6,"X_AM")+COUNTIF(Août!B12:R12,"X_AM")+COUNTIF(Septembre!B6:P6,"X_AM")+COUNTIF(Septembre!B12:R12,"X_AM")+COUNTIF(Octobre!B6:P6,"X_AM")+COUNTIF(Octobre!B12:R12,"X_AM")+COUNTIF(Novembre!B6:P6,"X_AM")+COUNTIF(Novembre!B12:R12,"X_AM")+COUNTIF(Décembre!B6:P6,"X_AM")+COUNTIF(Décembre!B12:R12,"X_AM") | C27: =B27*8 | D27: =B27*2
A28: X_PM | B28: =COUNTIF(Janvier!B6:P6,"X_PM")+COUNTIF(Janvier!B12:R12,"X_PM")+COUNTIF(Février!B6:P6,"X_PM")+COUNTIF(Février!B12:R12,"X_PM")+COUNTIF(Mars!B6:P6,"X_PM")+COUNTIF(Mars!B12:R12,"X_PM")+COUNTIF(Avril!B6:P6,"X_PM")+COUNTIF(Avril!B12:R12,"X_PM")+COUNTIF(Mai!B6:P6,"X_PM")+COUNTIF(Mai!B12:R12,"X_PM")+COUNTIF(Juin!B6:P6,"X_PM")+COUNTIF(Juin!B12:R12,"X_PM")+COUNTIF(Juillet!B6:P6,"X_PM")+COUNTIF(Juillet!B12:R12,"X_PM")+COUNTIF(Août!B6:P6,"X_PM")+COUNTIF(Août!B12:R12,"X_PM")+COUNTIF(Septembre!B6:P6,"X_PM")+COUNTIF(Septembre!B12:R12,"X_PM")+COUNTIF(Octobre!B6:P6,"X_PM")+COUNTIF(Octobre!B12:R12,"X_PM")+COUNTIF(Novembre!B6:P6,"X_PM")+COUNTIF(Novembre!B12:R12,"X_PM")+COUNTIF(Décembre!B6:P6,"X_PM")+COUNTIF(Décembre!B12:R12,"X_PM") | C28: =B28*8 | D28: =B28*2
A29: X_10 | B29: =COUNTIF(Janvier!B6:P6,"X_10")+COUNTIF(Janvier!B12:R12,"X_10")+COUNTIF(Février!B6:P6,"X_10")+COUNTIF(Février!B12:R12,"X_10")+COUNTIF(Mars!B6:P6,"X_10")+COUNTIF(Mars!B12:R12,"X_10")+COUNTIF(Avril!B6:P6,"X_10")+COUNTIF(Avril!B12:R12,"X_10")+COUNTIF(Mai!B6:P6,"X_10")+COUNTIF(Mai!B12:R12,"X_10")+COUNTIF(Juin!B6:P6,"X_10")+COUNTIF(Juin!B12:R12,"X_10")+COUNTIF(Juillet!B6:P6,"X_10")+COUNTIF(Juillet!B12:R12,"X_10")+COUNTIF(Août!B6:P6,"X_10")+COUNTIF(Août!B12:R12,"X_10")+COUNTIF(Septembre!B6:P6,"X_10")+COUNTIF(Septembre!B12:R12,"X_10")+COUNTIF(Octobre!B6:P6,"X_10")+COUNTIF(Octobre!B12:R12,"X_10")+COUNTIF(Novembre!B6:P6,"X_10")+COUNTIF(Novembre!B12:R12,"X_10")+COUNTIF(Décembre!B6:P6,"X_10")+COUNTIF(Décembre!B12:R12,"X_10") | C29: =B29*8 | D29: 0
A30: AG | B30: =COUNTIF(Janvier!B6:P6,"AG")+COUNTIF(Janvier!B12:R12,"AG")+COUNTIF(Février!B6:P6,"AG")+COUNTIF(Février!B12:R12,"AG")+COUNTIF(Mars!B6:P6,"AG")+COUNTIF(Mars!B12:R12,"AG")+COUNTIF(Avril!B6:P6,"AG")+COUNTIF(Avril!B12:R12,"AG")+COUNTIF(Mai!B6:P6,"AG")+COUNTIF(Mai!B12:R12,"AG")+COUNTIF(Juin!B6:P6,"AG")+COUNTIF(Juin!B12:R12,"AG")+COUNTIF(Juillet!B6:P6,"AG")+COUNTIF(Juillet!B12:R12,"AG")+COUNTIF(Août!B6:P6,"AG")+COUNTIF(Août!B12:R12,"AG")+COUNTIF(Septembre!B6:P6,"AG")+COUNTIF(Septembre!B12:R12,"AG")+COUNTIF(Octobre!B6:P6,"AG")+COUNTIF(Octobre!B12:R12,"AG")+COUNTIF(Novembre!B6:P6,"AG")+COUNTIF(Novembre!B12:R12,"AG")+COUNTIF(Décembre!B6:P6,"AG")+COUNTIF(Décembre!B12:R12,"AG") | C30: =B30*8 | D30: 0
A31: CN | B31: =COUNTIF(Janvier!B6:P6,"CN")+COUNTIF(Janvier!B12:R12,"CN")+COUNTIF(Février!B6:P6,"CN")+COUNTIF(Février!B12:R12,"CN")+COUNTIF(Mars!B6:P6,"CN")+COUNTIF(Mars!B12:R12,"CN")+COUNTIF(Avril!B6:P6,"CN")+COUNTIF(Avril!B12:R12,"CN")+COUNTIF(Mai!B6:P6,"CN")+COUNTIF(Mai!B12:R12,"CN")+COUNTIF(Juin!B6:P6,"CN")+COUNTIF(Juin!B12:R12,"CN")+COUNTIF(Juillet!B6:P6,"CN")+COUNTIF(Juillet!B12:R12,"CN")+COUNTIF(Août!B6:P6,"CN")+COUNTIF(Août!B12:R12,"CN")+COUNTIF(Septembre!B6:P6,"CN")+COUNTIF(Septembre!B12:R12,"CN")+COUNTIF(Octobre!B6:P6,"CN")+COUNTIF(Octobre!B12:R12,"CN")+COUNTIF(Novembre!B6:P6,"CN")+COUNTIF(Novembre!B12:R12,"CN")+COUNTIF(Décembre!B6:P6,"CN")+COUNTIF(Décembre!B12:R12,"CN") | C31: =B31*8 | D31: 0
A32: JC | B32: =COUNTIF(Janvier!B6:P6,"JC")+COUNTIF(Janvier!B12:R12,"JC")+COUNTIF(Février!B6:P6,"JC")+COUNTIF(Février!B12:R12,"JC")+COUNTIF(Mars!B6:P6,"JC")+COUNTIF(Mars!B12:R12,"JC")+COUNTIF(Avril!B6:P6,"JC")+COUNTIF(Avril!B12:R12,"JC")+COUNTIF(Mai!B6:P6,"JC")+COUNTIF(Mai!B12:R12,"JC")+COUNTIF(Juin!B6:P6,"JC")+COUNTIF(Juin!B12:R12,"JC")+COUNTIF(Juillet!B6:P6,"JC")+COUNTIF(Juillet!B12:R12,"JC")+COUNTIF(Août!B6:P6,"JC")+COUNTIF(Août!B12:R12,"JC")+COUNTIF(Septembre!B6:P6,"JC")+COUNTIF(Septembre!B12:R12,"JC")+COUNTIF(Octobre!B6:P6,"JC")+COUNTIF(Octobre!B12:R12,"JC")+COUNTIF(Novembre!B6:P6,"JC")+COUNTIF(Novembre!B12:R12,"JC")+COUNTIF(Décembre!B6:P6,"JC")+COUNTIF(Décembre!B12:R12,"JC") | C32: =B32*8 | D32: 0
A33: RH | B33: =COUNTIF(Janvier!B6:P6,"RH")+COUNTIF(Janvier!B12:R12,"RH")+COUNTIF(Février!B6:P6,"RH")+COUNTIF(Février!B12:R12,"RH")+COUNTIF(Mars!B6:P6,"RH")+COUNTIF(Mars!B12:R12,"RH")+COUNTIF(Avril!B6:P6,"RH")+COUNTIF(Avril!B12:R12,"RH")+COUNTIF(Mai!B6:P6,"RH")+COUNTIF(Mai!B12:R12,"RH")+COUNTIF(Juin!B6:P6,"RH")+COUNTIF(Juin!B12:R12,"RH")+COUNTIF(Juillet!B6:P6,"RH")+COUNTIF(Juillet!B12:R12,"RH")+COUNTIF(Août!B6:P6,"RH")+COUNTIF(Août!B12:R12,"RH")+COUNTIF(Septembre!B6:P6,"RH")+COUNTIF(Septembre!B12:R12,"RH")+COUNTIF(Octobre!B6:P6,"RH")+COUNTIF(Octobre!B12:R12,"RH")+COUNTIF(Novembre!B6:P6,"RH")+COUNTIF(Novembre!B12:R12,"RH")+COUNTIF(Décembre!B6:P6,"RH")+COUNTIF(Décembre!B12:R12,"RH") | C33: 0 | D33: 0
A34: CH | B34: =COUNTIF(Janvier!B6:P6,"CH")+COUNTIF(Janvier!B12:R12,"CH")+COUNTIF(Février!B6:P6,"CH")+COUNTIF(Février!B12:R12,"CH")+COUNTIF(Mars!B6:P6,"CH")+COUNTIF(Mars!B12:R12,"CH")+COUNTIF(Avril!B6:P6,"CH")+COUNTIF(Avril!B12:R12,"CH")+COUNTIF(Mai!B6:P6,"CH")+COUNTIF(Mai!B12:R12,"CH")+COUNTIF(Juin!B6:P6,"CH")+COUNTIF(Juin!B12:R12,"CH")+COUNTIF(Juillet!B6:P6,"CH")+COUNTIF(Juillet!B12:R12,"CH")+COUNTIF(Août!B6:P6,"CH")+COUNTIF(Août!B12:R12,"CH")+COUNTIF(Septembre!B6:P6,"CH")+COUNTIF(Septembre!B12:R12,"CH")+COUNTIF(Octobre!B6:P6,"CH")+COUNTIF(Octobre!B12:R12,"CH")+COUNTIF(Novembre!B6:P6,"CH")+COUNTIF(Novembre!B12:R12,"CH")+COUNTIF(Décembre!B6:P6,"CH")+COUNTIF(Décembre!B12:R12,"CH") | C34: 0 | D34: 0
A35: RR | B35: =COUNTIF(Janvier!B6:P6,"RR")+COUNTIF(Janvier!B12:R12,"RR")+COUNTIF(Février!B6:P6,"RR")+COUNTIF(Février!B12:R12,"RR")+COUNTIF(Mars!B6:P6,"RR")+COUNTIF(Mars!B12:R12,"RR")+COUNTIF(Avril!B6:P6,"RR")+COUNTIF(Avril!B12:R12,"RR")+COUNTIF(Mai!B6:P6,"RR")+COUNTIF(Mai!B12:R12,"RR")+COUNTIF(Juin!B6:P6,"RR")+COUNTIF(Juin!B12:R12,"RR")+COUNTIF(Juillet!B6:P6,"RR")+COUNTIF(Juillet!B12:R12,"RR")+COUNTIF(Août!B6:P6,"RR")+COUNTIF(Août!B12:R12,"RR")+COUNTIF(Septembre!B6:P6,"RR")+COUNTIF(Septembre!B12:R12,"RR")+COUNTIF(Octobre!B6:P6,"RR")+COUNTIF(Octobre!B12:R12,"RR")+COUNTIF(Novembre!B6:P6,"RR")+COUNTIF(Novembre!B12:R12,"RR")+COUNTIF(Décembre!B6:P6,"RR")+COUNTIF(Décembre!B12:R12,"RR") | C35: =B35*8 | D35: 0
A36: CV | B36: =COUNTIF(Janvier!B6:P6,"CV")+COUNTIF(Janvier!B12:R12,"CV")+COUNTIF(Février!B6:P6,"CV")+COUNTIF(Février!B12:R12,"CV")+COUNTIF(Mars!B6:P6,"CV")+COUNTIF(Mars!B12:R12,"CV")+COUNTIF(Avril!B6:P6,"CV")+COUNTIF(Avril!B12:R12,"CV")+COUNTIF(Mai!B6:P6,"CV")+COUNTIF(Mai!B12:R12,"CV")+COUNTIF(Juin!B6:P6,"CV")+COUNTIF(Juin!B12:R12,"CV")+COUNTIF(Juillet!B6:P6,"CV")+COUNTIF(Juillet!B12:R12,"CV")+COUNTIF(Août!B6:P6,"CV")+COUNTIF(Août!B12:R12,"CV")+COUNTIF(Septembre!B6:P6,"CV")+COUNTIF(Septembre!B12:R12,"CV")+COUNTIF(Octobre!B6:P6,"CV")+COUNTIF(Octobre!B12:R12,"CV")+COUNTIF(Novembre!B6:P6,"CV")+COUNTIF(Novembre!B12:R12,"CV")+COUNTIF(Décembre!B6:P6,"CV")+COUNTIF(Décembre!B12:R12,"CV") | C36: =B36*8 | D36: 0
A37: ZM | B37: =COUNTIF(Janvier!B6:P6,"ZM")+COUNTIF(Janvier!B12:R12,"ZM")+COUNTIF(Février!B6:P6,"ZM")+COUNTIF(Février!B12:R12,"ZM")+COUNTIF(Mars!B6:P6,"ZM")+COUNTIF(Mars!B12:R12,"ZM")+COUNTIF(Avril!B6:P6,"ZM")+COUNTIF(Avril!B12:R12,"ZM")+COUNTIF(Mai!B6:P6,"ZM")+COUNTIF(Mai!B12:R12,"ZM")+COUNTIF(Juin!B6:P6,"ZM")+COUNTIF(Juin!B12:R12,"ZM")+COUNTIF(Juillet!B6:P6,"ZM")+COUNTIF(Juillet!B12:R12,"ZM")+COUNTIF(Août!B6:P6,"ZM")+COUNTIF(Août!B12:R12,"ZM")+COUNTIF(Septembre!B6:P6,"ZM")+COUNTIF(Septembre!B12:R12,"ZM")+COUNTIF(Octobre!B6:P6,"ZM")+COUNTIF(Octobre!B12:R12,"ZM")+COUNTIF(Novembre!B6:P6,"ZM")+COUNTIF(Novembre!B12:R12,"ZM")+COUNTIF(Décembre!B6:P6,"ZM")+COUNTIF(Décembre!B12:R12,"ZM") | C37: =B37*8 | D37: 0
A38: TOTAL | C38: =SUM(C12:C37) | D38: =SUM(D12:D37)
A40: REPORT POUR 2027
A41: Type | B41: Droit | C41: Report | D41: Pris | E41: Solde
A42: CN | B42: =CONFIGURATION!B8 | C42: =CONFIGURATION!C8 | D42: =B31 | E42: =B42+C42-D42
A43: JC | B43: =CONFIGURATION!B9 | C43: =CONFIGURATION!C9 | D43: =B32 | E43: =B43+C43-D43

Sheet Janvier
A1: JANVIER 2026
A3: Jours 1-15
A4: Jour | B4: 1 | C4: 2 | D4: 3 | E4: 4 | F4: 5 | G4: 6 | H4: 7 | I4: 8 | J4: 9 | K4: 10 | L4: 11 | M4: 12 | N4: 13 | O4: 14 | P4: 15
A5: J.sem | B5: J | C5: V | D5: S | E5: D | F5: L | G5: M | H5: M | I5: J | J5: V | K5: S | L5: D | M5: L | N5: M | O5: M | P5: J
A6: Code
A7: Période | M7: P1 | N7: P1 | O7: P1 | P7: P1
A9: Jours 16-31
A10: Jour | B10: 16 | C10: 17 | D10: 18 | E10: 19 | F10: 20 | G10: 21 | H10: 22 | I10: 23 | J10: 24 | K10: 25 | L10: 26 | M10: 27 | N10: 28 | O10: 29 | P10: 30 | Q10: 31
A11: J.sem | B11: V | C11: S | D11: D | E11: L | F11: M | G11: M | H11: J | I11: V | J11: S | K11: D | L11: L | M11: M | N11: M | O11: J | P11: V | Q11: S
A12: Code
A13: Période | B13: P1 | C13: P1 | D13: P1 | E13: P1 | F13: P1 | G13: P1 | H13: P1 | I13: P1 | J13: P1 | K13: P1 | L13: P1 | M13: P1 | N13: P1 | O13: P1 | P13: P1 | Q13: P1
A16: Prestations | B16: Jours | C16: H. Totales | D16: H. Nuit | E16: Couleur
A17: 101 | B17: =COUNTIF(B6:P6,"101")+COUNTIF(B12:R12,"101") | C17: =B17*8 | D17: =B17*2
A18: 102 | B18: =COUNTIF(B6:P6,"102")+COUNTIF(B12:R12,"102") | C18: =B18*8 | D18: =B18*2
A19: 111 | B19: =COUNTIF(B6:P6,"111")+COUNTIF(B12:R12,"111") | C19: =B19*8 | D19: =B19*2
A20: 112 | B20: =COUNTIF(B6:P6,"112")+COUNTIF(B12:R12,"112") | C20: =B20*8 | D20: =B20*2
A21: 121 | B21: =COUNTIF(B6:P6,"121")+COUNTIF(B12:R12,"121") | C21: =B21*8 | D21: =B21*8
A22: 6101 | B22: =COUNTIF(B6:P6,"6101")+COUNTIF(B12:R12,"6101") | C22: =B22*8 | D22: =B22*2
A23: 6102 | B23: =COUNTIF(B6:P6,"6102")+COUNTIF(B12:R12,"6102") | C23: =B23*8 | D23: =B23*2
A24: 6111 | B24: =COUNTIF(B6:P6,"6111")+COUNTIF(B12:R12,"6111") | C24: =B24*8 | D24: =B24*2
A25: 6112 | B25: =COUNTIF(B6:P6,"6112")+COUNTIF(B12:R12,"6112") | C25: =B25*8 | D25: =B25*2
A26: 6121 | B26: =COUNTIF(B6:P6,"6121")+COUNTIF(B12:R12,"6121") | C26: =B26*8 | D26: =B26*8
A27: 7101 | B27: =COUNTIF(B6:P6,"7101")+COUNTIF(B12:R12,"7101") | C27: =B27*8 | D27: =B27*2
A28: 7102 | B28: =COUNTIF(B6:P6,"7102")+COUNTIF(B12:R12,"7102") | C28: =B28*8 | D28: =B28*2
A29: 7111 | B29: =COUNTIF(B6:P6,"7111")+COUNTIF(B12:R12,"7111") | C29: =B29*8 | D29: =B29*2
A30: 7112 | B30: =COUNTIF(B6:P6,"7112")+COUNTIF(B12:R12,"7112") | C30: =B30*8 | D30: =B30*2
A31: 7121 | B31: =COUNTIF(B6:P6,"7121")+COUNTIF(B12:R12,"7121") | C31: =B31*8 | D31: =B31*8
A32: X_AM | B32: =COUNTIF(B6:P6,"X_AM")+COUNTIF(B12:R12,"X_AM") | C32: =B32*8 | D32: =B32*2
A33: X_PM | B33: =COUNTIF(B6:P6,"X_PM")+COUNTIF(B12:R12,"X_PM") | C33: =B33*8 | D33: =B33*2
A34: X_10 | B34: =COUNTIF(B6:P6,"X_10")+COUNTIF(B12:R12,"X_10") | C34: =B34*8 | D34: 0
A35: AG | B35: =COUNTIF(B6:P6,"AG")+COUNTIF(B12:R12,"AG") | C35: =B35*8 | D35: 0
A36: TOTAL | B36: =SUM(B17:B35) | C36: =SUM(C17:C35) | D36: =SUM(D17:D35)
A38: REPOS | B38: Jours | C38: H. Totales | D38: H. Nuit | E38: Couleur
A39: CN | B39: =COUNTIF(B6:P6,"CN")+COUNTIF(B12:R12,"CN") | C39: =B39*8 | D39: 0
A40: JC | B40: =COUNTIF(B6:P6,"JC")+COUNTIF(B12:R12,"JC") | C40: =B40*8 | D40: 0
A41: RH | B41: =COUNTIF(B6:P6,"RH")+COUNTIF(B12:R12,"RH") | C41: 0 | D41: 0
A42: CH | B42: =COUNTIF(B6:P6,"CH")+COUNTIF(B12:R12,"CH") | C42: 0 | D42: 0
A43: RR | B43: =COUNTIF(B6:P6,"RR")+COUNTIF(B12:R12,"RR") | C43: =B43*8 | D43: 0
A44: CV | B44: =COUNTIF(B6:P6,"CV")+COUNTIF(B12:R12,"CV") | C44: =B44*8 | D44: 0
A45: ZM | B45: =COUNTIF(B6:P6,"ZM")+COUNTIF(B12:R12,"ZM") | C45: =B45*8 | D45: 0
...

Sheet Février
A1: FÉVRIER 2026
A3: Jours 1-15
A4: Jour | B4: 1 | C4: 2 | D4: 3 | E4: 4 | F4: 5 | G4: 6 | H4: 7 | I4: 8 | J4: 9 | K4: 10 | L4: 11 | M4: 12 | N4: 13 | O4: 14 | P4: 15
A5: J.sem | B5: D | C5: L | D5: M | E5: M | F5: J | G5: V | H5: S | I5: D | J5: L | K5: M | L5: M | M5: J | N5: V | O5: S | P5: D
A6: Code
A7: Période | B7: P1 | C7: P1 | D7: P1 | E7: P1 | F7: P1 | G7: P1 | H7: P1 | I7: P1 | J7: P2 | K7: P2 | L7: P2 | M7: P2 | N7: P2 | O7: P2 | P7: P2
A9: Jours 16-28
A10: Jour | B10: 16 | C10: 17 | D10: 18 | E10: 19 | F10: 20 | G10: 21 | H10: 22 | I10: 23 | J10: 24 | K10: 25 | L10: 26 | M10: 27 | N10: 28
A11: J.sem | B11: L | C11: M | D11: M | E11: J | F11: V | G11: S | H11: D | I11: L | J11: M | K11: M | L11: J | M11: V | N11: S
A12: Code
A13: Période | B13: P2 | C13: P2 | D13: P2 | E13: P2 | F13: P2 | G13: P2 | H13: P2 | I13: P2 | J13: P2 | K13: P2 | L13: P2 | M13: P2 | N13: P2
A16: Prestations | B16: Jours | C16: H. Totales | D16: H. Nuit | E16: Couleur
A17: 101 | B17: =COUNTIF(B6:P6,"101")+COUNTIF(B12:R12,"101") | C17: =B17*8 | D17: =B17*2
A18: 102 | B18: =COUNTIF(B6:P6,"102")+COUNTIF(B12:R12,"102") | C18: =B18*8 | D18: =B18*2
A19: 111 | B19: =COUNTIF(B6:P6,"111")+COUNTIF(B12:R12,"111") | C19: =B19*8 | D19: =B19*2
A20: 112 | B20: =COUNTIF(B6:P6,"112")+COUNTIF(B12:R12,"112") | C20: =B20*8 | D20: =B20*2
A21: 121 | B21: =COUNTIF(B6:P6,"121")+COUNTIF(B12:R12,"121") | C21: =B21*8 | D21: =B21*8
A22: 6101 | B22: =COUNTIF(B6:P6,"6101")+COUNTIF(B12:R12,"6101") | C22: =B22*8 | D22: =B22*2
A23: 6102 | B23: =COUNTIF(B6:P6,"6102")+COUNTIF(B12:R12,"6102") | C23: =B23*8 | D23: =B23*2
A24: 6111 | B24: =COUNTIF(B6:P6,"6111")+COUNTIF(B12:R12,"6111") | C24: =B24*8 | D24: =B24*2
A25: 6112 | B25: =COUNTIF(B6:P6,"6112")+COUNTIF(B12:R12,"6112") | C25: =B25*8 | D25: =B25*2
A26: 6121 | B26: =COUNTIF(B6:P6,"6121")+COUNTIF(B12:R12,"6121") | C26: =B26*8 | D26: =B26*8
A27: 7101 | B27: =COUNTIF(B6:P6,"7101")+COUNTIF(B12:R12,"7101") | C27: =B27*8 | D27: =B27*2
A28: 7102 | B28: =COUNTIF(B6:P6,"7102")+COUNTIF(B12:R12,"7102") | C28: =B28*8 | D28: =B28*2
A29: 7111 | B29: =COUNTIF(B6:P6,"7111")+COUNTIF(B12:R12,"7111") | C29: =B29*8 | D29: =B29*2
A30: 7112 | B30: =COUNTIF(B6:P6,"7112")+COUNTIF(B12:R12,"7112") | C30: =B30*8 | D30: =B30*2
A31: 7121 | B31: =COUNTIF(B6:P6,"7121")+COUNTIF(B12:R12,"7121") | C31: =B31*8 | D31: =B31*8
A32: X_AM | B32: =COUNTIF(B6:P6,"X_AM")+COUNTIF(B12:R12,"X_AM") | C32: =B32*8 | D32: =B32*2
A33: X_PM | B33: =COUNTIF(B6:P6,"X_PM")+COUNTIF(B12:R12,"X_PM") | C33: =B33*8 | D33: =B33*2
A34: X_10 | B34: =COUNTIF(B6:P6,"X_10")+COUNTIF(B12:R12,"X_10") | C34: =B34*8 | D34: 0
A35: AG | B35: =COUNTIF(B6:P6,"AG")+COUNTIF(B12:R12,"AG") | C35: =B35*8 | D35: 0
A36: TOTAL | B36: =SUM(B17:B35) | C36: =SUM(C17:C35) | D36: =SUM(D17:D35)
A38: REPOS | B38: Jours | C38: H. Totales | D38: H. Nuit | E38: Couleur
A39: CN | B39: =COUNTIF(B6:P6,"CN")+COUNTIF(B12:R12,"CN") | C39: =B39*8 | D39: 0
A40: JC | B40: =COUNTIF(B6:P6,"JC")+COUNTIF(B12:R12,"JC") | C40: =B40*8 | D40: 0
A41: RH | B41: =COUNTIF(B6:P6,"RH")+COUNTIF(B12:R12,"RH") | C41: 0 | D41: 0
A42: CH | B42: =COUNTIF(B6:P6,"CH")+COUNTIF(B12:R12,"CH") | C42: 0 | D42: 0
A43: RR | B43: =COUNTIF(B6:P6,"RR")+COUNTIF(B12:R12,"RR") | C43: =B43*8 | D43: 0
A44: CV | B44: =COUNTIF(B6:P6,"CV")+COUNTIF(B12:R12,"CV") | C44: =B44*8 | D44: 0
A45: ZM | B45: =COUNTIF(B6:P6,"ZM")+COUNTIF(B12:R12,"ZM") | C45: =B45*8 | D45: 0
...

Sheet Mars
A1: MARS 2026
A3: Jours 1-15
A4: Jour | B4: 1 | C4: 2 | D4: 3 | E4: 4 | F4: 5 | G4: 6 | H4: 7 | I4: 8 | J4: 9 | K4: 10 | L4: 11 | M4: 12 | N4: 13 | O4: 14 | P4: 15
A5: J.sem | B5: D | C5: L | D5: M | E5: M | F5: J | G5: V | H5: S | I5: D | J5: L | K5: M | L5: M | M5: J | N5: V | O5: S | P5: D
A6: Code
A7: Période | B7: P2 | C7: P2 | D7: P2 | E7: P2 | F7: P2 | G7: P2 | H7: P2 | I7: P2 | J7: P3 | K7: P3 | L7: P3 | M7: P3 | N7: P3 | O7: P3 | P7: P3
A9: Jours 16-31
A10: Jour | B10: 16 | C10: 17 | D10: 18 | E10: 19 | F10: 20 | G10: 21 | H10: 22 | I10: 23 | J10: 24 | K10: 25 | L10: 26 | M10: 27 | N10: 28 | O10: 29 | P10: 30 | Q10: 31
A11: J.sem | B11: L | C11: M | D11: M | E11: J | F11: V | G11: S | H11: D | I11: L | J11: M | K11: M | L11: J | M11: V | N11: S | O11: D | P11: L | Q11: M
A12: Code
A13: Période | B13: P3 | C13: P3 | D13: P3 | E13: P3 | F13: P3 | G13: P3 | H13: P3 | I13: P3 | J13: P3 | K13: P3 | L13: P3 | M13: P3 | N13: P3 | O13: P3 | P13: P3 | Q13: P3
A16: Prestations | B16: Jours | C16: H. Totales | D16: H. Nuit | E16: Couleur
A17: 101 | B17: =COUNTIF(B6:P6,"101")+COUNTIF(B12:R12,"101") | C17: =B17*8 | D17: =B17*2
A18: 102 | B18: =COUNTIF(B6:P6,"102")+COUNTIF(B12:R12,"102") | C18: =B18*8 | D18: =B18*2
A19: 111 | B19: =COUNTIF(B6:P6,"111")+COUNTIF(B12:R12,"111") | C19: =B19*8 | D19: =B19*2
A20: 112 | B20: =COUNTIF(B6:P6,"112")+COUNTIF(B12:R12,"112") | C20: =B20*8 | D20: =B20*2
A21: 121 | B21: =COUNTIF(B6:P6,"121")+COUNTIF(B12:R12,"121") | C21: =B21*8 | D21: =B21*8
A22: 6101 | B22: =COUNTIF(B6:P6,"6101")+COUNTIF(B12:R12,"6101") | C22: =B22*8 | D22: =B22*2
A23: 6102 | B23: =COUNTIF(B6:P6,"6102")+COUNTIF(B12:R12,"6102") | C23: =B23*8 | D23: =B23*2
A24: 6111 | B24: =COUNTIF(B6:P6,"6111")+COUNTIF(B12:R12,"6111") | C24: =B24*8 | D24: =B24*2
A25: 6112 | B25: =COUNTIF(B6:P6,"6112")+COUNTIF(B12:R12,"6112") | C25: =B25*8 | D25: =B25*2
A26: 6121 | B26: =COUNTIF(B6:P6,"6121")+COUNTIF(B12:R12,"6121") | C26: =B26*8 | D26: =B26*8
A27: 7101 | B27: =COUNTIF(B6:P6,"7101")+COUNTIF(B12:R12,"7101") | C27: =B27*8 | D27: =B27*2
A28: 7102 | B28: =COUNTIF(B6:P6,"7102")+COUNTIF(B12:R12,"7102") | C28: =B28*8 | D28: =B28*2
A29: 7111 | B29: =COUNTIF(B6:P6,"7111")+COUNTIF(B12:R12,"7111") | C29: =B29*8 | D29: =B29*2
A30: 7112 | B30: =COUNTIF(B6:P6,"7112")+COUNTIF(B12:R12,"7112") | C30: =B30*8 | D30: =B30*2
A31: 7121 | B31: =COUNTIF(B6:P6,"7121")+COUNTIF(B12:R12,"7121") | C31: =B31*8 | D31: =B31*8
A32: X_AM | B32: =COUNTIF(B6:P6,"X_AM")+COUNTIF(B12:R12,"X_AM") | C32: =B32*8 | D32: =B32*2
A33: X_PM | B33: =COUNTIF(B6:P6,"X_PM")+COUNTIF(B12:R12,"X_PM") | C33: =B33*8 | D33: =B33*2
A34: X_10 | B34: =COUNTIF(B6:P6,"X_10")+COUNTIF(B12:R12,"X_10") | C34: =B34*8 | D34: 0
A35: AG | B35: =COUNTIF(B6:P6,"AG")+COUNTIF(B12:R12,"AG") | C35: =B35*8 | D35: 0
A36: TOTAL | B36: =SUM(B17:B35) | C36: =SUM(C17:C35) | D36: =SUM(D17:D35)
A38: REPOS | B38: Jours | C38: H. Totales | D38: H. Nuit | E38: Couleur
A39: CN | B39: =COUNTIF(B6:P6,"CN")+COUNTIF(B12:R12,"CN") | C39: =B39*8 | D39: 0
A40: JC | B40: =COUNTIF(B6:P6,"JC")+COUNTIF(B12:R12,"JC") | C40: =B40*8 | D40: 0
A41: RH | B41: =COUNTIF(B6:P6,"RH")+COUNTIF(B12:R12,"RH") | C41: 0 | D41: 0
A42: CH | B42: =COUNTIF(B6:P6,"CH")+COUNTIF(B12:R12,"CH") | C42: 0 | D42: 0
A43: RR | B43: =COUNTIF(B6:P6,"RR")+COUNTIF(B12:R12,"RR") | C43: =B43*8 | D43: 0
A44: CV | B44: =COUNTIF(B6:P6,"CV")+COUNTIF(B12:R12,"CV") | C44: =B44*8 | D44: 0
A45: ZM | B45: =COUNTIF(B6:P6,"ZM")+COUNTIF(B12:R12,"ZM") | C45: =B45*8 | D45: 0
...

Sheet Avril
A1: AVRIL 2026
A3: Jours 1-15
A4: Jour | B4: 1 | C4: 2 | D4: 3 | E4: 4 | F4: 5 | G4: 6 | H4: 7 | I4: 8 | J4: 9 | K4: 10 | L4: 11 | M4: 12 | N4: 13 | O4: 14 | P4: 15
A5: J.sem | B5: M | C5: J | D5: V | E5: S | F5: D | G5: L | H5: M | I5: M | J5: J | K5: V | L5: S | M5: D | N5: L | O5: M | P5: M
A6: Code
A7: Période | B7: P3 | C7: P3 | D7: P3 | E7: P3 | F7: P3 | G7: P4 | H7: P4 | I7: P4 | J7: P4 | K7: P4 | L7: P4 | M7: P4 | N7: P4 | O7: P4 | P7: P4
A9: Jours 16-30
A10: Jour | B10: 16 | C10: 17 | D10: 18 | E10: 19 | F10: 20 | G10: 21 | H10: 22 | I10: 23 | J10: 24 | K10: 25 | L10: 26 | M10: 27 | N10: 28 | O10: 29 | P10: 30
A11: J.sem | B11: J | C11: V | D11: S | E11: D | F11: L | G11: M | H11: M | I11: J | J11: V | K11: S | L11: D | M11: L | N11: M | O11: M | P11: J
A12: Code
A13: Période | B13: P4 | C13: P4 | D13: P4 | E13: P4 | F13: P4 | G13: P4 | H13: P4 | I13: P4 | J13: P4 | K13: P4 | L13: P4 | M13: P4 | N13: P4 | O13: P4 | P13: P4
A16: Prestations | B16: Jours | C16: H. Totales | D16: H. Nuit | E16: Couleur
A17: 101 | B17: =COUNTIF(B6:P6,"101")+COUNTIF(B12:R12,"101") | C17: =B17*8 | D17: =B17*2
A18: 102 | B18: =COUNTIF(B6:P6,"102")+COUNTIF(B12:R12,"102") | C18: =B18*8 | D18: =B18*2
A19: 111 | B19: =COUNTIF(B6:P6,"111")+COUNTIF(B12:R12,"111") | C19: =B19*8 | D19: =B19*2
A20: 112 | B20: =COUNTIF(B6:P6,"112")+COUNTIF(B12:R12,"112") | C20: =B20*8 | D20: =B20*2
A21: 121 | B21: =COUNTIF(B6:P6,"121")+COUNTIF(B12:R12,"121") | C21: =B21*8 | D21: =B21*8
A22: 6101 | B22: =COUNTIF(B6:P6,"6101")+COUNTIF(B12:R12,"6101") | C22: =B22*8 | D22: =B22*2
A23: 6102 | B23: =COUNTIF(B6:P6,"6102")+COUNTIF(B12:R12,"6102") | C23: =B23*8 | D23: =B23*2
A24: 6111 | B24: =COUNTIF(B6:P6,"6111")+COUNTIF(B12:R12,"6111") | C24: =B24*8 | D24: =B24*2
A25: 6112 | B25: =COUNTIF(B6:P6,"6112")+COUNTIF(B12:R12,"6112") | C25: =B25*8 | D25: =B25*2
A26: 6121 | B26: =COUNTIF(B6:P6,"6121")+COUNTIF(B12:R12,"6121") | C26: =B26*8 | D26: =B26*8
A27: 7101 | B27: =COUNTIF(B6:P6,"7101")+COUNTIF(B12:R12,"7101") | C27: =B27*8 | D27: =B27*2
A28: 7102 | B28: =COUNTIF(B6:P6,"7102")+COUNTIF(B12:R12,"7102") | C28: =B28*8 | D28: =B28*2
A29: 7111 | B29: =COUNTIF(B6:P6,"7111")+COUNTIF(B12:R12,"7111") | C29: =B29*8 | D29: =B29*2
A30: 7112 | B30: =COUNTIF(B6:P6,"7112")+COUNTIF(B12:R12,"7112") | C30: =B30*8 | D30: =B30*2
A31: 7121 | B31: =COUNTIF(B6:P6,"7121")+COUNTIF(B12:R12,"7121") | C31: =B31*8 | D31: =B31*8
A32: X_AM | B32: =COUNTIF(B6:P6,"X_AM")+COUNTIF(B12:R12,"X_AM") | C32: =B32*8 | D32: =B32*2
A33: X_PM | B33: =COUNTIF(B6:P6,"X_PM")+COUNTIF(B12:R12,"X_PM") | C33: =B33*8 | D33: =B33*2
A34: X_10 | B34: =COUNTIF(B6:P6,"X_10")+COUNTIF(B12:R12,"X_10") | C34: =B34*8 | D34: 0
A35: AG | B35: =COUNTIF(B6:P6,"AG")+COUNTIF(B12:R12,"AG") | C35: =B35*8 | D35: 0
A36: TOTAL | B36: =SUM(B17:B35) | C36: =SUM(C17:C35) | D36: =SUM(D17:D35)
A38: REPOS | B38: Jours | C38: H. Totales | D38: H. Nuit | E38: Couleur
A39: CN | B39: =COUNTIF(B6:P6,"CN")+COUNTIF(B12:R12,"CN") | C39: =B39*8 | D39: 0
A40: JC | B40: =COUNTIF(B6:P6,"JC")+COUNTIF(B12:R12,"JC") | C40: =B40*8 | D40: 0
A41: RH | B41: =COUNTIF(B6:P6,"RH")+COUNTIF(B12:R12,"RH") | C41: 0 | D41: 0
A42: CH | B42: =COUNTIF(B6:P6,"CH")+COUNTIF(B12:R12,"CH") | C42: 0 | D42: 0
A43: RR | B43: =COUNTIF(B6:P6,"RR")+COUNTIF(B12:R12,"RR") | C43: =B43*8 | D43: 0
A44: CV | B44: =COUNTIF(B6:P6,"CV")+COUNTIF(B12:R12,"CV") | C44: =B44*8 | D44: 0
A45: ZM | B45: =COUNTIF(B6:P6,"ZM")+COUNTIF(B12:R12,"ZM") | C45: =B45*8 | D45: 0
...

Sheet Mai
A1: MAI 2026
A3: Jours 1-15
A4: Jour | B4: 1 | C4: 2 | D4: 3 | E4: 4 | F4: 5 | G4: 6 | H4: 7 | I4: 8 | J4: 9 | K4: 10 | L4: 11 | M4: 12 | N4: 13 | O4: 14 | P4: 15
A5: J.sem | B5: V | C5: S | D5: D | E5: L | F5: M | G5: M | H5: J | I5: V | J5: S | K5: D | L5: L | M5: M | N5: M | O5: J | P5: V
A6: Code
A7: Période | B7: P4 | C7: P4 | D7: P4 | E7: P5 | F7: P5 | G7: P5 | H7: P5 | I7: P5 | J7: P5 | K7: P5 | L7: P5 | M7: P5 | N7: P5 | O7: P5 | P7: P5
A9: Jours 16-31
A10: Jour | B10: 16 | C10: 17 | D10: 18 | E10: 19 | F10: 20 | G10: 21 | H10: 22 | I10: 23 | J10: 24 | K10: 25 | L10: 26 | M10: 27 | N10: 28 | O10: 29 | P10: 30 | Q10: 31
A11: J.sem | B11: S | C11: D | D11: L | E11: M | F11: M | G11: J | H11: V | I11: S | J11: D | K11: L | L11: M | M11: M | N11: J | O11: V | P11: S | Q11: D
A12: Code
A13: Période | B13: P5 | C13: P5 | D13: P5 | E13: P5 | F13: P5 | G13: P5 | H13: P5 | I13: P5 | J13: P5 | K13: P5 | L13: P5 | M13: P5 | N13: P5 | O13: P5 | P13: P5 | Q13: P5
A16: Prestations | B16: Jours | C16: H. Totales | D16: H. Nuit | E16: Couleur
A17: 101 | B17: =COUNTIF(B6:P6,"101")+COUNTIF(B12:R12,"101") | C17: =B17*8 | D17: =B17*2
A18: 102 | B18: =COUNTIF(B6:P6,"102")+COUNTIF(B12:R12,"102") | C18: =B18*8 | D18: =B18*2
A19: 111 | B19: =COUNTIF(B6:P6,"111")+COUNTIF(B12:R12,"111") | C19: =B19*8 | D19: =B19*2
A20: 112 | B20: =COUNTIF(B6:P6,"112")+COUNTIF(B12:R12,"112") | C20: =B20*8 | D20: =B20*2
A21: 121 | B21: =COUNTIF(B6:P6,"121")+COUNTIF(B12:R12,"121") | C21: =B21*8 | D21: =B21*8
A22: 6101 | B22: =COUNTIF(B6:P6,"6101")+COUNTIF(B12:R12,"6101") | C22: =B22*8 | D22: =B22*2
A23: 6102 | B23: =COUNTIF(B6:P6,"6102")+COUNTIF(B12:R12,"6102") | C23: =B23*8 | D23: =B23*2
A24: 6111 | B24: =COUNTIF(B6:P6,"6111")+COUNTIF(B12:R12,"6111") | C24: =B24*8 | D24: =B24*2
A25: 6112 | B25: =COUNTIF(B6:P6,"6112")+COUNTIF(B12:R12,"6112") | C25: =B25*8 | D25: =B25*2
A26: 6121 | B26: =COUNTIF(B6:P6,"6121")+COUNTIF(B12:R12,"6121") | C26: =B26*8 | D26: =B26*8
A27: 7101 | B27: =COUNTIF(B6:P6,"7101")+COUNTIF(B12:R12,"7101") | C27: =B27*8 | D27: =B27*2
A28: 7102 | B28: =COUNTIF(B6:P6,"7102")+COUNTIF(B12:R12,"7102") | C28: =B28*8 | D28: =B28*2
A29: 7111 | B29: =COUNTIF(B6:P6,"7111")+COUNTIF(B12:R12,"7111") | C29: =B29*8 | D29: =B29*2
A30: 7112 | B30: =COUNTIF(B6:P6,"7112")+COUNTIF(B12:R12,"7112") | C30: =B30*8 | D30: =B30*2
A31: 7121 | B31: =COUNTIF(B6:P6,"7121")+COUNTIF(B12:R12,"7121") | C31: =B31*8 | D31: =B31*8
A32: X_AM | B32: =COUNTIF(B6:P6,"X_AM")+COUNTIF(B12:R12,"X_AM") | C32: =B32*8 | D32: =B32*2
A33: X_PM | B33: =COUNTIF(B6:P6,"X_PM")+COUNTIF(B12:R12,"X_PM") | C33: =B33*8 | D33: =B33*2
A34: X_10 | B34: =COUNTIF(B6:P6,"X_10")+COUNTIF(B12:R12,"X_10") | C34: =B34*8 | D34: 0
A35: AG | B35: =COUNTIF(B6:P6,"AG")+COUNTIF(B12:R12,"AG") | C35: =B35*8 | D35: 0
A36: TOTAL | B36: =SUM(B17:B35) | C36: =SUM(C17:C35) | D36: =SUM(D17:D35)
A38: REPOS | B38: Jours | C38: H. Totales | D38: H. Nuit | E38: Couleur
A39: CN | B39: =COUNTIF(B6:P6,"CN")+COUNTIF(B12:R12,"CN") | C39: =B39*8 | D39: 0
A40: JC | B40: =COUNTIF(B6:P6,"JC")+COUNTIF(B12:R12,"JC") | C40: =B40*8 | D40: 0
A41: RH | B41: =COUNTIF(B6:P6,"RH")+COUNTIF(B12:R12,"RH") | C41: 0 | D41: 0
A42: CH | B42: =COUNTIF(B6:P6,"CH")+COUNTIF(B12:R12,"CH") | C42: 0 | D42: 0
A43: RR | B43: =COUNTIF(B6:P6,"RR")+COUNTIF(B12:R12,"RR") | C43: =B43*8 | D43: 0
A44: CV | B44: =COUNTIF(B6:P6,"CV")+COUNTIF(B12:R12,"CV") | C44: =B44*8 | D44: 0
A45: ZM | B45: =COUNTIF(B6:P6,"ZM")+COUNTIF(B12:R12,"ZM") | C45: =B45*8 | D45: 0
...

Sheet Juin
A1: JUIN 2026
A3: Jours 1-15
A4: Jour | B4: 1 | C4: 2 | D4: 3 | E4: 4 | F4: 5 | G4: 6 | H4: 7 | I4: 8 | J4: 9 | K4: 10 | L4: 11 | M4: 12 | N4: 13 | O4: 14 | P4: 15
A5: J.sem | B5: L | C5: M | D5: M | E5: J | F5: V | G5: S | H5: D | I5: L | J5: M | K5: M | L5: J | M5: V | N5: S | O5: D | P5: L
A6: Code
A7: Période | B7: P6 | C7: P6 | D7: P6 | E7: P6 | F7: P6 | G7: P6 | H7: P6 | I7: P6 | J7: P6 | K7: P6 | L7: P6 | M7: P6 | N7: P6 | O7: P6 | P7: P6
A9: Jours 16-30
A10: Jour | B10: 16 | C10: 17 | D10: 18 | E10: 19 | F10: 20 | G10: 21 | H10: 22 | I10: 23 | J10: 24 | K10: 25 | L10: 26 | M10: 27 | N10: 28 | O10: 29 | P10: 30
A11: J.sem | B11: M | C11: M | D11: J | E11: V | F11: S | G11: D | H11: L | I11: M | J11: M | K11: J | L11: V | M11: S | N11: D | O11: L | P11: M
A12: Code
A13: Période | B13: P6 | C13: P6 | D13: P6 | E13: P6 | F13: P6 | G13: P6 | H13: P6 | I13: P6 | J13: P6 | K13: P6 | L13: P6 | M13: P6 | N13: P6 | O13: P7 | P13: P7
A16: Prestations | B16: Jours | C16: H. Totales | D16: H. Nuit | E16: Couleur
A17: 101 | B17: =COUNTIF(B6:P6,"101")+COUNTIF(B12:R12,"101") | C17: =B17*8 | D17: =B17*2
A18: 102 | B18: =COUNTIF(B6:P6,"102")+COUNTIF(B12:R12,"102") | C18: =B18*8 | D18: =B18*2
A19: 111 | B19: =COUNTIF(B6:P6,"111")+COUNTIF(B12:R12,"111") | C19: =B19*8 | D19: =B19*2
A20: 112 | B20: =COUNTIF(B6:P6,"112")+COUNTIF(B12:R12,"112") | C20: =B20*8 | D20: =B20*2
A21: 121 | B21: =COUNTIF(B6:P6,"121")+COUNTIF(B12:R12,"121") | C21: =B21*8 | D21: =B21*8
A22: 6101 | B22: =COUNTIF(B6:P6,"6101")+COUNTIF(B12:R12,"6101") | C22: =B22*8 | D22: =B22*2
A23: 6102 | B23: =COUNTIF(B6:P6,"6102")+COUNTIF(B12:R12,"6102") | C23: =B23*8 | D23: =B23*2
A24: 6111 | B24: =COUNTIF(B6:P6,"6111")+COUNTIF(B12:R12,"6111") | C24: =B24*8 | D24: =B24*2
A25: 6112 | B25: =COUNTIF(B6:P6,"6112")+COUNTIF(B12:R12,"6112") | C25: =B25*8 | D25: =B25*2
A26: 6121 | B26: =COUNTIF(B6:P6,"6121")+COUNTIF(B12:R12,"6121") | C26: =B26*8 | D26: =B26*8
A27: 7101 | B27: =COUNTIF(B6:P6,"7101")+COUNTIF(B12:R12,"7101") | C27: =B27*8 | D27: =B27*2
A28: 7102 | B28: =COUNTIF(B6:P6,"7102")+COUNTIF(B12:R12,"7102") | C28: =B28*8 | D28: =B28*2
A29: 7111 | B29: =COUNTIF(B6:P6,"7111")+COUNTIF(B12:R12,"7111") | C29: =B29*8 | D29: =B29*2
A30: 7112 | B30: =COUNTIF(B6:P6,"7112")+COUNTIF(B12:R12,"7112") | C30: =B30*8 | D30: =B30*2
A31: 7121 | B31: =COUNTIF(B6:P6,"7121")+COUNTIF(B12:R12,"7121") | C31: =B31*8 | D31: =B31*8
A32: X_AM | B32: =COUNTIF(B6:P6,"X_AM")+COUNTIF(B12:R12,"X_AM") | C32: =B32*8 | D32: =B32*2
A33: X_PM | B33: =COUNTIF(B6:P6,"X_PM")+COUNTIF(B12:R12,"X_PM") | C33: =B33*8 | D33: =B33*2
A34: X_10 | B34: =COUNTIF(B6:P6,"X_10")+COUNTIF(B12:R12,"X_10") | C34: =B34*8 | D34: 0
A35: AG | B35: =COUNTIF(B6:P6,"AG")+COUNTIF(B12:R12,"AG") | C35: =B35*8 | D35: 0
A36: TOTAL | B36: =SUM(B17:B35) | C36: =SUM(C17:C35) | D36: =SUM(D17:D35)
A38: REPOS | B38: Jours | C38: H. Totales | D38: H. Nuit | E38: Couleur
A39: CN | B39: =COUNTIF(B6:P6,"CN")+COUNTIF(B12:R12,"CN") | C39: =B39*8 | D39: 0
A40: JC | B40: =COUNTIF(B6:P6,"JC")+COUNTIF(B12:R12,"JC") | C40: =B40*8 | D40: 0
A41: RH | B41: =COUNTIF(B6:P6,"RH")+COUNTIF(B12:R12,"RH") | C41: 0 | D41: 0
A42: CH | B42: =COUNTIF(B6:P6,"CH")+COUNTIF(B12:R12,"CH") | C42: 0 | D42: 0
A43: RR | B43: =COUNTIF(B6:P6,"RR")+COUNTIF(B12:R12,"RR") | C43: =B43*8 | D43: 0
A44: CV | B44: =COUNTIF(B6:P6,"CV")+COUNTIF(B12:R12,"CV") | C44: =B44*8 | D44: 0
A45: ZM | B45: =COUNTIF(B6:P6,"ZM")+COUNTIF(B12:R12,"ZM") | C45: =B45*8 | D45: 0
...

Sheet Juillet
A1: JUILLET 2026
A3: Jours 1-15
A4: Jour | B4: 1 | C4: 2 | D4: 3 | E4: 4 | F4: 5 | G4: 6 | H4: 7 | I4: 8 | J4: 9 | K4: 10 | L4: 11 | M4: 12 | N4: 13 | O4: 14 | P4: 15
A5: J.sem | B5: M | C5: J | D5: V | E5: S | F5: D | G5: L | H5: M | I5: M | J5: J | K5: V | L5: S | M5: D | N5: L | O5: M | P5: M
A6: Code
A7: Période | B7: P7 | C7: P7 | D7: P7 | E7: P7 | F7: P7 | G7: P7 | H7: P7 | I7: P7 | J7: P7 | K7: P7 | L7: P7 | M7: P7 | N7: P7 | O7: P7 | P7: P7
A9: Jours 16-31
A10: Jour | B10: 16 | C10: 17 | D10: 18 | E10: 19 | F10: 20 | G10: 21 | H10: 22 | I10: 23 | J10: 24 | K10: 25 | L10: 26 | M10: 27 | N10: 28 | O10: 29 | P10: 30 | Q10: 31
A11: J.sem | B11: J | C11: V | D11: S | E11: D | F11: L | G11: M | H11: M | I11: J | J11: V | K11: S | L11: D | M11: L | N11: M | O11: M | P11: J | Q11: V
A12: Code
A13: Période | B13: P7 | C13: P7 | D13: P7 | E13: P7 | F13: P7 | G13: P7 | H13: P7 | I13: P7 | J13: P7 | K13: P7 | L13: P7 | M13: P8 | N13: P8 | O13: P8 | P13: P8 | Q13: P8
A16: Prestations | B16: Jours | C16: H. Totales | D16: H. Nuit | E16: Couleur
A17: 101 | B17: =COUNTIF(B6:P6,"101")+COUNTIF(B12:R12,"101") | C17: =B17*8 | D17: =B17*2
A18: 102 | B18: =COUNTIF(B6:P6,"102")+COUNTIF(B12:R12,"102") | C18: =B18*8 | D18: =B18*2
A19: 111 | B19: =COUNTIF(B6:P6,"111")+COUNTIF(B12:R12,"111") | C19: =B19*8 | D19: =B19*2
A20: 112 | B20: =COUNTIF(B6:P6,"112")+COUNTIF(B12:R12,"112") | C20: =B20*8 | D20: =B20*2
A21: 121 | B21: =COUNTIF(B6:P6,"121")+COUNTIF(B12:R12,"121") | C21: =B21*8 | D21: =B21*8
A22: 6101 | B22: =COUNTIF(B6:P6,"6101")+COUNTIF(B12:R12,"6101") | C22: =B22*8 | D22: =B22*2
A23: 6102 | B23: =COUNTIF(B6:P6,"6102")+COUNTIF(B12:R12,"6102") | C23: =B23*8 | D23: =B23*2
A24: 6111 | B24: =COUNTIF(B6:P6,"6111")+COUNTIF(B12:R12,"6111") | C24: =B24*8 | D24: =B24*2
A25: 6112 | B25: =COUNTIF(B6:P6,"6112")+COUNTIF(B12:R12,"6112") | C25: =B25*8 | D25: =B25*2
A26: 6121 | B26: =COUNTIF(B6:P6,"6121")+COUNTIF(B12:R12,"6121") | C26: =B26*8 | D26: =B26*8
A27: 7101 | B27: =COUNTIF(B6:P6,"7101")+COUNTIF(B12:R12,"7101") | C27: =B27*8 | D27: =B27*2
A28: 7102 | B28: =COUNTIF(B6:P6,"7102")+COUNTIF(B12:R12,"7102") | C28: =B28*8 | D28: =B28*2
A29: 7111 | B29: =COUNTIF(B6:P6,"7111")+COUNTIF(B12:R12,"7111") | C29: =B29*8 | D29: =B29*2
A30: 7112 | B30: =COUNTIF(B6:P6,"7112")+COUNTIF(B12:R12,"7112") | C30: =B30*8 | D30: =B30*2
A31: 7121 | B31: =COUNTIF(B6:P6,"7121")+COUNTIF(B12:R12,"7121") | C31: =B31*8 | D31: =B31*8
A32: X_AM | B32: =COUNTIF(B6:P6,"X_AM")+COUNTIF(B12:R12,"X_AM") | C32: =B32*8 | D32: =B32*2
A33: X_PM | B33: =COUNTIF(B6:P6,"X_PM")+COUNTIF(B12:R12,"X_PM") | C33: =B33*8 | D33: =B33*2
A34: X_10 | B34: =COUNTIF(B6:P6,"X_10")+COUNTIF(B12:R12,"X_10") | C34: =B34*8 | D34: 0
A35: AG | B35: =COUNTIF(B6:P6,"AG")+COUNTIF(B12:R12,"AG") | C35: =B35*8 | D35: 0
A36: TOTAL | B36: =SUM(B17:B35) | C36: =SUM(C17:C35) | D36: =SUM(D17:D35)
A38: REPOS | B38: Jours | C38: H. Totales | D38: H. Nuit | E38: Couleur
A39: CN | B39: =COUNTIF(B6:P6,"CN")+COUNTIF(B12:R12,"CN") | C39: =B39*8 | D39: 0
A40: JC | B40: =COUNTIF(B6:P6,"JC")+COUNTIF(B12:R12,"JC") | C40: =B40*8 | D40: 0
A41: RH | B41: =COUNTIF(B6:P6,"RH")+COUNTIF(B12:R12,"RH") | C41: 0 | D41: 0
A42: CH | B42: =COUNTIF(B6:P6,"CH")+COUNTIF(B12:R12,"CH") | C42: 0 | D42: 0
A43: RR | B43: =COUNTIF(B6:P6,"RR")+COUNTIF(B12:R12,"RR") | C43: =B43*8 | D43: 0
A44: CV | B44: =COUNTIF(B6:P6,"CV")+COUNTIF(B12:R12,"CV") | C44: =B44*8 | D44: 0
A45: ZM | B45: =COUNTIF(B6:P6,"ZM")+COUNTIF(B12:R12,"ZM") | C45: =B45*8 | D45: 0
...

Sheet Août
A1: AOÛT 2026
A3: Jours 1-15
A4: Jour | B4: 1 | C4: 2 | D4: 3 | E4: 4 | F4: 5 | G4: 6 | H4: 7 | I4: 8 | J4: 9 | K4: 10 | L4: 11 | M4: 12 | N4: 13 | O4: 14 | P4: 15
A5: J.sem | B5: S | C5: D | D5: L | E5: M | F5: M | G5: J | H5: V | I5: S | J5: D | K5: L | L5: M | M5: M | N5: J | O5: V | P5: S
A6: Code
A7: Période | B7: P8 | C7: P8 | D7: P8 | E7: P8 | F7: P8 | G7: P8 | H7: P8 | I7: P8 | J7: P8 | K7: P8 | L7: P8 | M7: P8 | N7: P8 | O7: P8 | P7: P8
A9: Jours 16-31
A10: Jour | B10: 16 | C10: 17 | D10: 18 | E10: 19 | F10: 20 | G10: 21 | H10: 22 | I10: 23 | J10: 24 | K10: 25 | L10: 26 | M10: 27 | N10: 28 | O10: 29 | P10: 30 | Q10: 31
A11: J.sem | B11: D | C11: L | D11: M | E11: M | F11: J | G11: V | H11: S | I11: D | J11: L | K11: M | L11: M | M11: J | N11: V | O11: S | P11: D | Q11: L
A12: Code
A13: Période | B13: P8 | C13: P8 | D13: P8 | E13: P8 | F13: P8 | G13: P8 | H13: P8 | I13: P8 | J13: P9 | K13: P9 | L13: P9 | M13: P9 | N13: P9 | O13: P9 | P13: P9 | Q13: P9
A16: Prestations | B16: Jours | C16: H. Totales | D16: H. Nuit | E16: Couleur
A17: 101 | B17: =COUNTIF(B6:P6,"101")+COUNTIF(B12:R12,"101") | C17: =B17*8 | D17: =B17*2
A18: 102 | B18: =COUNTIF(B6:P6,"102")+COUNTIF(B12:R12,"102") | C18: =B18*8 | D18: =B18*2
A19: 111 | B19: =COUNTIF(B6:P6,"111")+COUNTIF(B12:R12,"111") | C19: =B19*8 | D19: =B19*2
A20: 112 | B20: =COUNTIF(B6:P6,"112")+COUNTIF(B12:R12,"112") | C20: =B20*8 | D20: =B20*2
A21: 121 | B21: =COUNTIF(B6:P6,"121")+COUNTIF(B12:R12,"121") | C21: =B21*8 | D21: =B21*8
A22: 6101 | B22: =COUNTIF(B6:P6,"6101")+COUNTIF(B12:R12,"6101") | C22: =B22*8 | D22: =B22*2
A23: 6102 | B23: =COUNTIF(B6:P6,"6102")+COUNTIF(B12:R12,"6102") | C23: =B23*8 | D23: =B23*2
A24: 6111 | B24: =COUNTIF(B6:P6,"6111")+COUNTIF(B12:R12,"6111") | C24: =B24*8 | D24: =B24*2
A25: 6112 | B25: =COUNTIF(B6:P6,"6112")+COUNTIF(B12:R12,"6112") | C25: =B25*8 | D25: =B25*2
A26: 6121 | B26: =COUNTIF(B6:P6,"6121")+COUNTIF(B12:R12,"6121") | C26: =B26*8 | D26: =B26*8
A27: 7101 | B27: =COUNTIF(B6:P6,"7101")+COUNTIF(B12:R12,"7101") | C27: =B27*8 | D27: =B27*2
A28: 7102 | B28: =COUNTIF(B6:P6,"7102")+COUNTIF(B12:R12,"7102") | C28: =B28*8 | D28: =B28*2
A29: 7111 | B29: =COUNTIF(B6:P6,"7111")+COUNTIF(B12:R12,"7111") | C29: =B29*8 | D29: =B29*2
A30: 7112 | B30: =COUNTIF(B6:P6,"7112")+COUNTIF(B12:R12,"7112") | C30: =B30*8 | D30: =B30*2
A31: 7121 | B31: =COUNTIF(B6:P6,"7121")+COUNTIF(B12:R12,"7121") | C31: =B31*8 | D31: =B31*8
A32: X_AM | B32: =COUNTIF(B6:P6,"X_AM")+COUNTIF(B12:R12,"X_AM") | C32: =B32*8 | D32: =B32*2
A33: X_PM | B33: =COUNTIF(B6:P6,"X_PM")+COUNTIF(B12:R12,"X_PM") | C33: =B33*8 | D33: =B33*2
A34: X_10 | B34: =COUNTIF(B6:P6,"X_10")+COUNTIF(B12:R12,"X_10") | C34: =B34*8 | D34: 0
A35: AG | B35: =COUNTIF(B6:P6,"AG")+COUNTIF(B12:R12,"AG") | C35: =B35*8 | D35: 0
A36: TOTAL | B36: =SUM(B17:B35) | C36: =SUM(C17:C35) | D36: =SUM(D17:D35)
A38: REPOS | B38: Jours | C38: H. Totales | D38: H. Nuit | E38: Couleur
A39: CN | B39: =COUNTIF(B6:P6,"CN")+COUNTIF(B12:R12,"CN") | C39: =B39*8 | D39: 0
A40: JC | B40: =COUNTIF(B6:P6,"JC")+COUNTIF(B12:R12,"JC") | C40: =B40*8 | D40: 0
A41: RH | B41: =COUNTIF(B6:P6,"RH")+COUNTIF(B12:R12,"RH") | C41: 0 | D41: 0
A42: CH | B42: =COUNTIF(B6:P6,"CH")+COUNTIF(B12:R12,"CH") | C42: 0 | D42: 0
A43: RR | B43: =COUNTIF(B6:P6,"RR")+COUNTIF(B12:R12,"RR") | C43: =B43*8 | D43: 0
A44: CV | B44: =COUNTIF(B6:P6,"CV")+COUNTIF(B12:R12,"CV") | C44: =B44*8 | D44: 0
A45: ZM | B45: =COUNTIF(B6:P6,"ZM")+COUNTIF(B12:R12,"ZM") | C45: =B45*8 | D45: 0
...

Sheet Septembre
A1: SEPTEMBRE 2026
A3: Jours 1-15
A4: Jour | B4: 1 | C4: 2 | D4: 3 | E4: 4 | F4: 5 | G4: 6 | H4: 7 | I4: 8 | J4: 9 | K4: 10 | L4: 11 | M4: 12 | N4: 13 | O4: 14 | P4: 15
A5: J.sem | B5: M | C5: M | D5: J | E5: V | F5: S | G5: D | H5: L | I5: M | J5: M | K5: J | L5: V | M5: S | N5: D | O5: L | P5: M
A6: Code
A7: Période | B7: P9 | C7: P9 | D7: P9 | E7: P9 | F7: P9 | G7: P9 | H7: P9 | I7: P9 | J7: P9 | K7: P9 | L7: P9 | M7: P9 | N7: P9 | O7: P9 | P7: P9
A9: Jours 16-30
A10: Jour | B10: 16 | C10: 17 | D10: 18 | E10: 19 | F10: 20 | G10: 21 | H10: 22 | I10: 23 | J10: 24 | K10: 25 | L10: 26 | M10: 27 | N10: 28 | O10: 29 | P10: 30
A11: J.sem | B11: M | C11: J | D11: V | E11: S | F11: D | G11: L | H11: M | I11: M | J11: J | K11: V | L11: S | M11: D | N11: L | O11: M | P11: M
A12: Code
A13: Période | B13: P9 | C13: P9 | D13: P9 | E13: P9 | F13: P9 | G13: P10 | H13: P10 | I13: P10 | J13: P10 | K13: P10 | L13: P10 | M13: P10 | N13: P10 | O13: P10 | P13: P10
A16: Prestations | B16: Jours | C16: H. Totales | D16: H. Nuit | E16: Couleur
A17: 101 | B17: =COUNTIF(B6:P6,"101")+COUNTIF(B12:R12,"101") | C17: =B17*8 | D17: =B17*2
A18: 102 | B18: =COUNTIF(B6:P6,"102")+COUNTIF(B12:R12,"102") | C18: =B18*8 | D18: =B18*2
A19: 111 | B19: =COUNTIF(B6:P6,"111")+COUNTIF(B12:R12,"111") | C19: =B19*8 | D19: =B19*2
A20: 112 | B20: =COUNTIF(B6:P6,"112")+COUNTIF(B12:R12,"112") | C20: =B20*8 | D20: =B20*2
A21: 121 | B21: =COUNTIF(B6:P6,"121")+COUNTIF(B12:R12,"121") | C21: =B21*8 | D21: =B21*8
A22: 6101 | B22: =COUNTIF(B6:P6,"6101")+COUNTIF(B12:R12,"6101") | C22: =B22*8 | D22: =B22*2
A23: 6102 | B23: =COUNTIF(B6:P6,"6102")+COUNTIF(B12:R12,"6102") | C23: =B23*8 | D23: =B23*2
A24: 6111 | B24: =COUNTIF(B6:P6,"6111")+COUNTIF(B12:R12,"6111") | C24: =B24*8 | D24: =B24*2
A25: 6112 | B25: =COUNTIF(B6:P6,"6112")+COUNTIF(B12:R12,"6112") | C25: =B25*8 | D25: =B25*2
A26: 6121 | B26: =COUNTIF(B6:P6,"6121")+COUNTIF(B12:R12,"6121") | C26: =B26*8 | D26: =B26*8
A27: 7101 | B27: =COUNTIF(B6:P6,"7101")+COUNTIF(B12:R12,"7101") | C27: =B27*8 | D27: =B27*2
A28: 7102 | B28: =COUNTIF(B6:P6,"7102")+COUNTIF(B12:R12,"7102") | C28: =B28*8 | D28: =B28*2
A29: 7111 | B29: =COUNTIF(B6:P6,"7111")+COUNTIF(B12:R12,"7111") | C29: =B29*8 | D29: =B29*2
A30: 7112 | B30: =COUNTIF(B6:P6,"7112")+COUNTIF(B12:R12,"7112") | C30: =B30*8 | D30: =B30*2
A31: 7121 | B31: =COUNTIF(B6:P6,"7121")+COUNTIF(B12:R12,"7121") | C31: =B31*8 | D31: =B31*8
A32: X_AM | B32: =COUNTIF(B6:P6,"X_AM")+COUNTIF(B12:R12,"X_AM") | C32: =B32*8 | D32: =B32*2
A33: X_PM | B33: =COUNTIF(B6:P6,"X_PM")+COUNTIF(B12:R12,"X_PM") | C33: =B33*8 | D33: =B33*2
A34: X_10 | B34: =COUNTIF(B6:P6,"X_10")+COUNTIF(B12:R12,"X_10") | C34: =B34*8 | D34: 0
A35: AG | B35: =COUNTIF(B6:P6,"AG")+COUNTIF(B12:R12,"AG") | C35: =B35*8 | D35: 0
A36: TOTAL | B36: =SUM(B17:B35) | C36: =SUM(C17:C35) | D36: =SUM(D17:D35)
A38: REPOS | B38: Jours | C38: H. Totales | D38: H. Nuit | E38: Couleur
A39: CN | B39: =COUNTIF(B6:P6,"CN")+COUNTIF(B12:R12,"CN") | C39: =B39*8 | D39: 0
A40: JC | B40: =COUNTIF(B6:P6,"JC")+COUNTIF(B12:R12,"JC") | C40: =B40*8 | D40: 0
A41: RH | B41: =COUNTIF(B6:P6,"RH")+COUNTIF(B12:R12,"RH") | C41: 0 | D41: 0
A42: CH | B42: =COUNTIF(B6:P6,"CH")+COUNTIF(B12:R12,"CH") | C42: 0 | D42: 0
A43: RR | B43: =COUNTIF(B6:P6,"RR")+COUNTIF(B12:R12,"RR") | C43: =B43*8 | D43: 0
A44: CV | B44: =COUNTIF(B6:P6,"CV")+COUNTIF(B12:R12,"CV") | C44: =B44*8 | D44: 0
A45: ZM | B45: =COUNTIF(B6:P6,"ZM")+COUNTIF(B12:R12,"ZM") | C45: =B45*8 | D45: 0
...

Sheet Octobre
A1: OCTOBRE 2026
A3: Jours 1-15
A4: Jour | B4: 1 | C4: 2 | D4: 3 | E4: 4 | F4: 5 | G4: 6 | H4: 7 | I4: 8 | J4: 9 | K4: 10 | L4: 11 | M4: 12 | N4: 13 | O4: 14 | P4: 15
A5: J.sem | B5: J | C5: V | D5: S | E5: D | F5: L | G5: M | H5: M | I5: J | J5: V | K5: S | L5: D | M5: L | N5: M | O5: M | P5: J
A6: Code
A7: Période | B7: P10 | C7: P10 | D7: P10 | E7: P10 | F7: P10 | G7: P10 | H7: P10 | I7: P10 | J7: P10 | K7: P10 | L7: P10 | M7: P10 | N7: P10 | O7: P10 | P7: P10
A9: Jours 16-31
A10: Jour | B10: 16 | C10: 17 | D10: 18 | E10: 19 | F10: 20 | G10: 21 | H10: 22 | I10: 23 | J10: 24 | K10: 25 | L10: 26 | M10: 27 | N10: 28 | O10: 29 | P10: 30 | Q10: 31
A11: J.sem | B11: V | C11: S | D11: D | E11: L | F11: M | G11: M | H11: J | I11: V | J11: S | K11: D | L11: L | M11: M | N11: M | O11: J | P11: V | Q11: S
A12: Code
A13: Période | B13: P10 | C13: P10 | D13: P10 | E13: P11 | F13: P11 | G13: P11 | H13: P11 | I13: P11 | J13: P11 | K13: P11 | L13: P11 | M13: P11 | N13: P11 | O13: P11 | P13: P11 | Q13: P11
A16: Prestations | B16: Jours | C16: H. Totales | D16: H. Nuit | E16: Couleur
A17: 101 | B17: =COUNTIF(B6:P6,"101")+COUNTIF(B12:R12,"101") | C17: =B17*8 | D17: =B17*2
A18: 102 | B18: =COUNTIF(B6:P6,"102")+COUNTIF(B12:R12,"102") | C18: =B18*8 | D18: =B18*2
A19: 111 | B19: =COUNTIF(B6:P6,"111")+COUNTIF(B12:R12,"111") | C19: =B19*8 | D19: =B19*2
A20: 112 | B20: =COUNTIF(B6:P6,"112")+COUNTIF(B12:R12,"112") | C20: =B20*8 | D20: =B20*2
A21: 121 | B21: =COUNTIF(B6:P6,"121")+COUNTIF(B12:R12,"121") | C21: =B21*8 | D21: =B21*8
A22: 6101 | B22: =COUNTIF(B6:P6,"6101")+COUNTIF(B12:R12,"6101") | C22: =B22*8 | D22: =B22*2
A23: 6102 | B23: =COUNTIF(B6:P6,"6102")+COUNTIF(B12:R12,"6102") | C23: =B23*8 | D23: =B23*2
A24: 6111 | B24: =COUNTIF(B6:P6,"6111")+COUNTIF(B12:R12,"6111") | C24: =B24*8 | D24: =B24*2
A25: 6112 | B25: =COUNTIF(B6:P6,"6112")+COUNTIF(B12:R12,"6112") | C25: =B25*8 | D25: =B25*2
A26: 6121 | B26: =COUNTIF(B6:P6,"6121")+COUNTIF(B12:R12,"6121") | C26: =B26*8 | D26: =B26*8
A27: 7101 | B27: =COUNTIF(B6:P6,"7101")+COUNTIF(B12:R12,"7101") | C27: =B27*8 | D27: =B27*2
A28: 7102 | B28: =COUNTIF(B6:P6,"7102")+COUNTIF(B12:R12,"7102") | C28: =B28*8 | D28: =B28*2
A29: 7111 | B29: =COUNTIF(B6:P6,"7111")+COUNTIF(B12:R12,"7111") | C29: =B29*8 | D29: =B29*2
A30: 7112 | B30: =COUNTIF(B6:P6,"7112")+COUNTIF(B12:R12,"7112") | C30: =B30*8 | D30: =B30*2
A31: 7121 | B31: =COUNTIF(B6:P6,"7121")+COUNTIF(B12:R12,"7121") | C31: =B31*8 | D31: =B31*8
A32: X_AM | B32: =COUNTIF(B6:P6,"X_AM")+COUNTIF(B12:R12,"X_AM") | C32: =B32*8 | D32: =B32*2
A33: X_PM | B33: =COUNTIF(B6:P6,"X_PM")+COUNTIF(B12:R12,"X_PM") | C33: =B33*8 | D33: =B33*2
A34: X_10 | B34: =COUNTIF(B6:P6,"X_10")+COUNTIF(B12:R12,"X_10") | C34: =B34*8 | D34: 0
A35: AG | B35: =COUNTIF(B6:P6,"AG")+COUNTIF(B12:R12,"AG") | C35: =B35*8 | D35: 0
A36: TOTAL | B36: =SUM(B17:B35) | C36: =SUM(C17:C35) | D36: =SUM(D17:D35)
A38: REPOS | B38: Jours | C38: H. Totales | D38: H. Nuit | E38: Couleur
A39: CN | B39: =COUNTIF(B6:P6,"CN")+COUNTIF(B12:R12,"CN") | C39: =B39*8 | D39: 0
A40: JC | B40: =COUNTIF(B6:P6,"JC")+COUNTIF(B12:R12,"JC") | C40: =B40*8 | D40: 0
A41: RH | B41: =COUNTIF(B6:P6,"RH")+COUNTIF(B12:R12,"RH") | C41: 0 | D41: 0
A42: CH | B42: =COUNTIF(B6:P6,"CH")+COUNTIF(B12:R12,"CH") | C42: 0 | D42: 0
A43: RR | B43: =COUNTIF(B6:P6,"RR")+COUNTIF(B12:R12,"RR") | C43: =B43*8 | D43: 0
A44: CV | B44: =COUNTIF(B6:P6,"CV")+COUNTIF(B12:R12,"CV") | C44: =B44*8 | D44: 0
A45: ZM | B45: =COUNTIF(B6:P6,"ZM")+COUNTIF(B12:R12,"ZM") | C45: =B45*8 | D45: 0
...

Sheet Novembre
A1: NOVEMBRE 2026
A3: Jours 1-15
A4: Jour | B4: 1 | C4: 2 | D4: 3 | E4: 4 | F4: 5 | G4: 6 | H4: 7 | I4: 8 | J4: 9 | K4: 10 | L4: 11 | M4: 12 | N4: 13 | O4: 14 | P4: 15
A5: J.sem | B5: D | C5: L | D5: M | E5: M | F5: J | G5: V | H5: S | I5: D | J5: L | K5: M | L5: M | M5: J | N5: V | O5: S | P5: D
A6: Code
A7: Période | B7: P11 | C7: P11 | D7: P11 | E7: P11 | F7: P11 | G7: P11 | H7: P11 | I7: P11 | J7: P11 | K7: P11 | L7: P11 | M7: P11 | N7: P11 | O7: P11 | P7: P11
A9: Jours 16-30
A10: Jour | B10: 16 | C10: 17 | D10: 18 | E10: 19 | F10: 20 | G10: 21 | H10: 22 | I10: 23 | J10: 24 | K10: 25 | L10: 26 | M10: 27 | N10: 28 | O10: 29 | P10: 30
A11: J.sem | B11: L | C11: M | D11: M | E11: J | F11: V | G11: S | H11: D | I11: L | J11: M | K11: M | L11: J | M11: V | N11: S | O11: D | P11: L
A12: Code
A13: Période | B13: P12 | C13: P12 | D13: P12 | E13: P12 | F13: P12 | G13: P12 | H13: P12 | I13: P12 | J13: P12 | K13: P12 | L13: P12 | M13: P12 | N13: P12 | O13: P12 | P13: P12
A16: Prestations | B16: Jours | C16: H. Totales | D16: H. Nuit | E16: Couleur
A17: 101 | B17: =COUNTIF(B6:P6,"101")+COUNTIF(B12:R12,"101") | C17: =B17*8 | D17: =B17*2
A18: 102 | B18: =COUNTIF(B6:P6,"102")+COUNTIF(B12:R12,"102") | C18: =B18*8 | D18: =B18*2
A19: 111 | B19: =COUNTIF(B6:P6,"111")+COUNTIF(B12:R12,"111") | C19: =B19*8 | D19: =B19*2
A20: 112 | B20: =COUNTIF(B6:P6,"112")+COUNTIF(B12:R12,"112") | C20: =B20*8 | D20: =B20*2
A21: 121 | B21: =COUNTIF(B6:P6,"121")+COUNTIF(B12:R12,"121") | C21: =B21*8 | D21: =B21*8
A22: 6101 | B22: =COUNTIF(B6:P6,"6101")+COUNTIF(B12:R12,"6101") | C22: =B22*8 | D22: =B22*2
A23: 6102 | B23: =COUNTIF(B6:P6,"6102")+COUNTIF(B12:R12,"6102") | C23: =B23*8 | D23: =B23*2
A24: 6111 | B24: =COUNTIF(B6:P6,"6111")+COUNTIF(B12:R12,"6111") | C24: =B24*8 | D24: =B24*2
A25: 6112 | B25: =COUNTIF(B6:P6,"6112")+COUNTIF(B12:R12,"6112") | C25: =B25*8 | D25: =B25*2
A26: 6121 | B26: =COUNTIF(B6:P6,"6121")+COUNTIF(B12:R12,"6121") | C26: =B26*8 | D26: =B26*8
A27: 7101 | B27: =COUNTIF(B6:P6,"7101")+COUNTIF(B12:R12,"7101") | C27: =B27*8 | D27: =B27*2
A28: 7102 | B28: =COUNTIF(B6:P6,"7102")+COUNTIF(B12:R12,"7102") | C28: =B28*8 | D28: =B28*2
A29: 7111 | B29: =COUNTIF(B6:P6,"7111")+COUNTIF(B12:R12,"7111") | C29: =B29*8 | D29: =B29*2
A30: 7112 | B30: =COUNTIF(B6:P6,"7112")+COUNTIF(B12:R12,"7112") | C30: =B30*8 | D30: =B30*2
A31: 7121 | B31: =COUNTIF(B6:P6,"7121")+COUNTIF(B12:R12,"7121") | C31: =B31*8 | D31: =B31*8
A32: X_AM | B32: =COUNTIF(B6:P6,"X_AM")+COUNTIF(B12:R12,"X_AM") | C32: =B32*8 | D32: =B32*2
A33: X_PM | B33: =COUNTIF(B6:P6,"X_PM")+COUNTIF(B12:R12,"X_PM") | C33: =B33*8 | D33: =B33*2
A34: X_10 | B34: =COUNTIF(B6:P6,"X_10")+COUNTIF(B12:R12,"X_10") | C34: =B34*8 | D34: 0
A35: AG | B35: =COUNTIF(B6:P6,"AG")+COUNTIF(B12:R12,"AG") | C35: =B35*8 | D35: 0
A36: TOTAL | B36: =SUM(B17:B35) | C36: =SUM(C17:C35) | D36: =SUM(D17:D35)
A38: REPOS | B38: Jours | C38: H. Totales | D38: H. Nuit | E38: Couleur
A39: CN | B39: =COUNTIF(B6:P6,"CN")+COUNTIF(B12:R12,"CN") | C39: =B39*8 | D39: 0
A40: JC | B40: =COUNTIF(B6:P6,"JC")+COUNTIF(B12:R12,"JC") | C40: =B40*8 | D40: 0
